Workbook
Name Budgeted_year: '[1]Setup Fields'!$B$1
Name Currency: '[1]Setup Fields'!$H$30
Name CurrencyChoice: '[1]Setup Fields'!$F$30
Name data_type: '[1]Setup Fields'!$A$67:$A$71
Name data_type_Short: '[1]Setup Fields'!$B$67:$B$71
Name Dept_Table: '[1]Dept Settings'!$A$2:$K$261
Name FTEHours: '[1]Setup Fields'!$B$10
Name Hotel_Name: '[1]Setup Fields'!$B$3
Name InflationRate: '[1]Setup Fields'!$B$11
Name PSF_FixedCost: '[1]Setup Fields'!$A$162
Name PSF_PercentageGRR: '[1]Setup Fields'!$A$163
Name PSF_PerKey: '[1]Setup Fields'!$A$164
Name WageIncrease: '[1]Setup Fields'!$B$13

Sheet Cover
D28: The foregoing information is based upon a variety of assumptions and estimates.
D29: There can be no assurance that the projections stated will be realized. Actual results may vary significantly from those shown.

Sheet Pricing Structure Description
D2: Product Item | E2: Spark | F2: Spark + | G2: Blaze | H2: Internal Notes | I2: Availability
D3: Description | E3: Small operations, such as start ups, single tenant | F3: Small operations that need a bit more configuration to drive usage, Single Tenant | G3: Core offering, Tentant, and Sub-tenant | H3: Enterprise, Organization, Department
B4: Reoccuring | C4: Base | D4: Licensing | E4: User | F4: User | G4: Site + 2 Users | H4: Site + Users
D5: Reoccurring fee
C6: Support | D6: Support | E6: E-mail, Chat | F6: E-mail, Chat | G6: Call, E-mail, Chat
D7: Support Guidelines | E7: E-mail 8:00 am ET - 8:00 pm ET, Chat: 8:00am ET- 8 pm ET | F7: E-mail 8:00 am ET - 8:00 pm ET, Chat: 8:00am ET- 8 pm ET | G7: E-mail 8:00 am ET - 8:00 pm ET, Chat: 24 hr., Call: Customer Success 8:00 ET - 8:00 pm ET
D8: Support Fee | E8: 50 | G8: 100
B9: One Time | C9: Configuration | D9: Configuration | E9: Limited Functionality, Templatized | F9: Limited, Functionality, templatized by industry, small configuration to enable user experience | G9: Full Functionality, configured for the organization
D10: Configuration Guidelines | G10: First four hours included in fee, additional fees- One Time Fee
D11: Configuration Fee | E11: N/A | F11: $250 hourly rate | G11: $250 hourly rate
C12: On-boarding | D12: Onboarding- User Training | E12: User Experience | F12: Wizardry, with the ability to purchase hours- E-training | G12: Up to 10 ppl per session, Two 1-hour sessions- E-training
D13: Onboarding- User Training Fee | E13: N/A | F13: $200 per hour | G13: $600 per session
D14: Onboarding- Administrator | E14: Templatized | F14: wizardry, with the ability to purchase hours | G14: On-boarding training of Administrators, up to 3 administrators, Three 1-hour sessions
D15: Onboarding- Administrator Fee | E15: N/A | F15: $200 per hour | G15: $600 per session
C16: Import | D16: Import | E16: spreadsheet mapping | F16: API- Configuration tool (ETL)- DOMO | G16: API- We Build, $100 per hour
D17: Import Fee | E17: N/A | G17: $150 per hour
D19: Thought Leadership Library | H19: Access to thought library content per license
D20: Consultancy | H20: Four hour session, that can be allocated at user's discretion.
D22: Ignite Talent

Sheet Pricing Calcuator
C3: Pricing Matrix
C6: Type of User | D6: License | E6: User
C7: Hospitality | D7: 250
C8: Hospitality Reseller | D8: 100
C9: Real Estate | D9: 400
C10: Real Estate Reseller | D10: 250
C11: Pharma | D11: 400
C12: Pharma- Reseller | D12: 250
C13: Small Start ups | D13: 150
C14: Small Start ups Reseller | D14: 75
C16: Pricing Calculator
C17: Rate Sheet
E18: Subscription | G18: One-Time Cost | I18: Description
C20: =C6 | D20: Hospitality | E20: =IF(D20="","",IF(D20=$C$7,$D$7,IF(D20=$C$8,D8,IF(D20=$C$9,D9,IF(D20=$C$11,D11,IF(D20=$C$12,D12,IF(D20=$C$10,D10,IF(D20=$C$13,D13,IF(D20=$C$14,D14)))))))))
C22: Number of
C23: Sites | D23: 5 | E23: =E20*D23 | I23: With each site license you will receive 2 users
C24: Additional User | D24: 10 | E24: =(E23*D24)*0.5 | I24: Additional User licenses over an above the 2 per site, 50% discount for additional users
C26: =C68 | D26: Support Blaze | E26: =IF(D26="","",IF(D26=C69,D69,IF(D26=C70,D70))) | I26: =IF(D26="","",IF(D26=C69,'Pricing Structure Description'!F7,IF('Pricing Calcuator'!D26='Pricing Calcuator'!C70,'Pricing Structure Description'!G7)))
C28: Number of Months | E28: 12
C30: One- Time Fees
C31: =C73 | D31: Blaze | G31: =IF(D31="","",IF(D31=$C$74,D74,IF(D31=$C$75,D75)))*D32 | I31: =IF(D31="","",IF(D31=C74,'Pricing Structure Description'!F9,IF('Pricing Calcuator'!D31='Pricing Calcuator'!C75,'Pricing Structure Description'!G9)))
C32: Number of hours | D32: 10
C33: Importing | D33: Blaze | G33: =D86*D23 | I33: =IF(D6="","",IF(D33=C75,'Pricing Structure Description'!G16,IF('Pricing Calcuator'!D33='Pricing Calcuator'!C74,'Pricing Structure Description'!F16)))
C36: =C77
C37: Administrator Training | D37: Yes | F37: =IF(D37="","",IF(D37=C79,D79,IF(D37=C80,D80))) | G37: =F37*D38 | I37: ='Pricing Structure Description'!G14
C38: If yes, number of Administrators | D38: 3
C40: User Training | D40: Yes | F40: =IF(D40="","",IF(D40=C82,D82,IF(D40=C83,D83))) | G40: =D41*F40 | I40: ='Pricing Structure Description'!G12
C41: If yes, number of sessions | D41: 5
C43: =C88 | E43: =IF(D44="","",IF(D44=C90,D90,IF(D44=C91,D91)))
C44: =C89 | D44: Yes | E44: =E43*D23 | I44: =IF(D44="","",IF(D44=C90,'Pricing Structure Description'!G11,IF('Pricing Calcuator'!D44='Pricing Calcuator'!C91,'Pricing Structure Description'!H19)))
C46: Consultancy Services | D46: Yes | G46: =IF(D46="","",IF(D46=C93,D93,IF(D46=C94,D94))) | I46: =IF(D46="","",IF(D46=C93,'Pricing Structure Description'!G12,IF('Pricing Calcuator'!D46='Pricing Calcuator'!C94,'Pricing Structure Description'!H22)))
E49: =((E23+E24+E26)*E28)+E44 | G49: =SUM(G20:G48)
C51: First Year | E51: =E49+G49
C53: =C84 | D53: Yes | E53: =E49*0.2
C54: Year Commitment | D54: 2 | E54: =IF(D54>1,((E49*D54)-E53),IF(D54<1,0)) | I54: Multi-Year with Discount of 20% per year
C56: Total Investment | E56: =E54+G49
C61: Outline of Service
C62: Service | D62: Pricing | E62: Offering | F62: Description
C63: Reoccuring
C64: Site / User
...

Sheet Revenue 2025
C3: 2025 | D3: Pricing
C4: Offerings and Distribution | D4: Price | E4: COGS | F4: Margin Per Subscription
C5: Administrative | H5: Growth Model
C6: Configuration | D6: 250 | E6: 50 | F6: =D6-E6
C7: On-Boarding- Administrator | D7: 500 | E7: 100 | F7: =D7-E7
C8: On-Boarding Users | D8: 500 | E8: 100 | F8: =D8-E8
C9: Import | D9: ='Pricing Calcuator'!D86 | E9: 600 | F9: =D9-E9
C10: Support | D10: 100 | E10: 50 | F10: =D10-E10
C11: Industry Break Down | E11: ='COGS Analysis'!D18
C12: Hospitality | D12: 250 | E12: ='Revenue 2030'!$Q$210 | F12: =D12-E12
C13: Hospitality- Reseller | D13: 100 | E13: ='Revenue 2030'!$Q$210 | F13: =D13-E13
C14: Real Estate Development | D14: 400 | E14: ='Revenue 2030'!$Q$210 | F14: =D14-E14
C15: Real Estate Development- Reseller | D15: 250 | E15: ='Revenue 2030'!$Q$210 | F15: =D15-E15
C16: Pharma | D16: 400 | E16: ='Revenue 2030'!$Q$210 | F16: =D16-E16
C17: Pharma- Reseller | D17: 250 | E17: ='Revenue 2030'!$Q$210 | F17: =D17-E17
C18: Start up - Small Firms | D18: 200 | E18: ='Revenue 2030'!$Q$210 | F18: =D18-E18
C19: Start up Reseller | D19: 100 | E19: ='Revenue 2030'!$Q$210 | F19: =D19-E19
C20: Training / Consultancy Training as a Service
C21: Thought Library | D21: 50 | E21: 25 | F21: =D21-E21
C22: Consultancy Services | D22: 225 | E22: 125 | F22: =D22-E22
C24: Segments | D24: January | E24: February | F24: March | G24: April | H24: May | I24: June | J24: July | K24: August | L24: September | M24: October | N24: November | O24: December | P24: Annual Totals | Q24: Profit Margin | R24: Profit margin comparison | S24: CHURN
B26: Hospitality | C26: =C12 | T26: Assumptions
C27: Licences Sold | D27: 120 | E27: 120 | F27: 150 | G27: 150 | H27: 160 | I27: 175 | J27: 250 | K27: 300 | L27: 325 | M27: 325 | N27: 325 | O27: 325 | P27: =O27 | S27: 0.03
D28: =D27*$S$27 | E28: =E27*$S$27 | F28: =F27*$S$27 | G28: =G27*$S$27 | H28: =H27*$S$27 | I28: =I27*$S$27 | J28: =J27*$S$27 | K28: =K27*$S$27 | ... O28: =O27*$S$27
C29: Total Sales | D29: =(D27-D28)*$D$12 | E29: =E27*$D$12 | F29: =F27*$D$12 | G29: =G27*$D$12 | H29: =H27*$D$12 | I29: =I27*$D$12 | J29: =J27*$D$12 | K29: =K27*$D$12 | L29: =L27*$D$12 | ... O29: =O27*$D$12 | P29: =SUM(D29:O29) | Q29: =(Q30+Q31) | T29: t Growing first within the hotel B2B market and looking for strategic partners and resellers, i.e. BI
C30: Total COGS | D30: =D27*$E$12 | E30: =E27*$E$12 | F30: =F27*$E$12 | G30: =G27*$E$12 | H30: =H27*$E$12 | I30: =I27*$E$12 | J30: =J27*$E$12 | K30: =K27*$E$12 | ... O30: =O27*$E$12 | P30: =SUM(D30:O30) | Q30: =IF(P29=0,0,P30/P29)
C31: Total Margin | D31: =D29-D30 | E31: =E29-E30 | F31: =F29-F30 | G31: =G29-G30 | H31: =H29-H30 | I31: =I29-I30 | J31: =J29-J30 | K31: =K29-K30 | ... O31: =O29-O30 | P31: =SUM(D31:O31) | Q31: =IF(P29=0,0,P31/P29)
T32: t The growth coming from Strategic Partners
C33: =C13
C34: Licences Sold | D34: 0 | E34: 0 | F34: 0 | G34: 0 | H34: 0 | I34: 0 | J34: 0 | K34: 0 | L34: 0 | M34: 0 | N34: 0 | O34: 0 | P34: =O34 | T34: t Sales coming from current team
C35: Total Sales | D35: =D34*$D$13 | E35: =E34*$D$13 | F35: =F34*$D$13 | G35: =G34*$D$13 | H35: =H34*$D$13 | I35: =I34*$D$13 | J35: =J34*$D$13 | K35: =K34*$D$13 | ... O35: =O34*$D$13 | P35: =SUM(D35:O35) | Q35: =(Q36+Q37)
C36: Total COGS | D36: =D34*$E$13 | E36: =E34*$E$13 | F36: =F34*$E$13 | G36: =G34*$E$13 | H36: =H34*$E$13 | I36: =I34*$E$13 | J36: =J34*$E$13 | K36: =K34*$E$13 | ... O36: =O34*$E$13 | P36: =SUM(D36:O36) | Q36: =IF(P35=0,0,P36/P35)
C37: Total Margin | D37: =D35-D36 | E37: =E35-E36 | F37: =F35-F36 | G37: =G35-G36 | H37: =H35-H36 | I37: =I35-I36 | J37: =J35-J36 | K37: =K35-K36 | ... O37: =O35-O36 | P37: =SUM(D37:O37) | Q37: =IF(P35=0,0,P37/P35)
B39: Real Estate | C39: =C14
C40: Licences Sold | D40: 50 | E40: 50 | F40: 50 | G40: 50 | H40: 50 | I40: 175 | J40: 175 | K40: 180 | L40: 180 | M40: 200 | N40: 200 | O40: 230 | P40: =O40
C41: Total Sales | D41: =D40*$D$14 | E41: =E40*$D$14 | F41: =F40*$D$14 | G41: =G40*$D$14 | H41: =H40*$D$14 | I41: =I40*$D$14 | J41: =J40*$D$14 | K41: =K40*$D$14 | ... O41: =O40*$D$14 | P41: =SUM(D41:O41) | Q41: =(Q42+Q43)
C42: Total COGS | D42: =D40*$E$14 | E42: =E40*$E$14 | F42: =F40*$E$14 | G42: =G40*$E$14 | H42: =H40*$E$14 | I42: =I40*$E$14 | J42: =J40*$E$14 | K42: =K40*$E$14 | ... O42: =O40*$E$14 | P42: =SUM(D42:O42) | Q42: =IF(P41=0,0,P42/P41)
C43: Total Margin | D43: =D41-D42 | E43: =E41-E42 | F43: =F41-F42 | G43: =G41-G42 | H43: =H41-H42 | I43: =I41-I42 | J43: =J41-J42 | K43: =K41-K42 | ... O43: =O41-O42 | P43: =SUM(D43:O43) | Q43: =IF(P41=0,0,P43/P41)
C45: =C15
C46: Licences Sold | D46: 0 | E46: 0 | F46: 0 | G46: 0 | H46: 0 | I46: 0 | J46: 0 | K46: 0 | L46: 0 | M46: 0 | N46: 0 | O46: 0 | P46: =O46
...

Sheet Revenue 2026
C3: 2026 | D3: Pricing
C4: Offerings and Distribution | D4: Price | E4: COGS | F4: Margin Per Subscription
C5: Administrative
C6: Configuration | D6: 250 | E6: 50 | F6: =D6-E6
C7: On-Boarding- Administrator | D7: 500 | E7: 100 | F7: =D7-E7
C8: On-Boarding Users | D8: 500 | E8: 100 | F8: =D8-E8
C9: Import | D9: ='Pricing Calcuator'!D86 | E9: 600 | F9: =D9-E9
C10: Support | D10: 100 | E10: 50 | F10: =D10-E10
C11: Industry Break Down | E11: ='COGS Analysis'!D18
C12: Hospitality | D12: 250 | E12: ='Revenue 2030'!$Q$210 | F12: =D12-E12
C13: Hospitality- Reseller | D13: 150 | E13: ='Revenue 2030'!$Q$210 | F13: =D13-E13
C14: Real Estate Development | D14: 400 | E14: ='Revenue 2030'!$Q$210 | F14: =D14-E14
C15: Real Estate Development- Reseller | D15: 250 | E15: ='Revenue 2030'!$Q$210 | F15: =D15-E15
C16: Pharma | D16: 400 | E16: ='Revenue 2030'!$Q$210 | F16: =D16-E16
C17: Pharma- Reseller | D17: 250 | E17: ='Revenue 2030'!$Q$210 | F17: =D17-E17
C18: Start up - Small Firms | D18: 200 | E18: ='Revenue 2030'!$Q$210 | F18: =D18-E18
C19: Start up Reseller | D19: 100 | E19: ='Revenue 2030'!$Q$210 | F19: =D19-E19
C20: Training / Consultancy Training as a Service
C21: Thought Library | D21: 50 | E21: 25 | F21: =D21-E21
C22: Consultancy Services | D22: 225 | E22: 125 | F22: =D22-E22
C24: Segments | D24: January | E24: February | F24: March | G24: April | H24: May | I24: June | J24: July | K24: August | L24: September | M24: October | N24: November | O24: December | P24: Annual Totals | Q24: Profit Margin | R24: Profit margin comparison | S24: Churn
B26: Hospitality | C26: =C12
C27: Licences Sold | D27: 340 | E27: 350 | F27: 360 | G27: 380 | H27: 390 | I27: 400 | J27: 425 | K27: 425 | L27: 475 | M27: 490 | N27: 490 | O27: 490 | P27: =O27 | S27: 0.03 | T27: Assumptions
D28: =D27*$S$27 | E28: =E27*$S$27 | F28: =F27*$S$27 | G28: =G27*$S$27 | H28: =H27*$S$27 | I28: =I27*$S$27 | J28: =J27*$S$27 | K28: =K27*$S$27 | ... O28: =O27*$S$27
C29: Total Sales | D29: =(D27-D28)*$D$12 | E29: =(E27-E28)*$D$12 | F29: =(F27-F28)*$D$12 | G29: =(G27-G28)*$D$12 | H29: =(H27-H28)*$D$12 | I29: =(I27-I28)*$D$12 | J29: =(J27-J28)*$D$12 | K29: =(K27-K28)*$D$12 | ... O29: =(O27-O28)*$D$12 | P29: =SUM(D29:O29) | Q29: =(Q30+Q31)
C30: Total COGS | D30: =D27*$E$12 | E30: =E27*$E$12 | F30: =F27*$E$12 | G30: =G27*$E$12 | H30: =H27*$E$12 | I30: =I27*$E$12 | J30: =J27*$E$12 | K30: =K27*$E$12 | ... O30: =O27*$E$12 | P30: =SUM(D30:O30) | Q30: =IF(P29=0,0,P30/P29)
C31: Total Margin | D31: =D29-D30 | E31: =E29-E30 | F31: =F29-F30 | G31: =G29-G30 | H31: =H29-H30 | I31: =I29-I30 | J31: =J29-J30 | K31: =K29-K30 | ... O31: =O29-O30 | P31: =SUM(D31:O31) | Q31: =IF(P29=0,0,P31/P29) | T31: t Additional sales person added to focus on Hospitality - Real Estate both B2B and Reseller
C33: =C13 | T33: t Growth within partners ships with Development companies, i.e. CBRE or smaller entrants
C34: Licences Sold | D34: 10 | E34: 20 | F34: 40 | G34: 50 | H34: 90 | I34: 100 | J34: 125 | K34: 135 | L34: 150 | M34: 160 | N34: 200 | O34: 200 | P34: =O34 | S34: 0.03
D35: =D34*S34
C36: Total Sales | D36: =(D34-D35)*$D$13 | E36: =E34*$D$13 | F36: =F34*$D$13 | G36: =G34*$D$13 | H36: =H34*$D$13 | I36: =I34*$D$13 | J36: =J34*$D$13 | K36: =K34*$D$13 | L36: =L34*$D$13 | ... O36: =O34*$D$13 | P36: =SUM(D36:O36) | Q36: =(Q37+Q38) | T36: t Thought library usage is based on 35% of new users purhasing the thought library access
C37: Total COGS | D37: =D34*$E$13 | E37: =E34*$E$13 | F37: =F34*$E$13 | G37: =G34*$E$13 | H37: =H34*$E$13 | I37: =I34*$E$13 | J37: =J34*$E$13 | K37: =K34*$E$13 | ... O37: =O34*$E$13 | P37: =SUM(D37:O37) | Q37: =IF(P36=0,0,P37/P36)
C38: Total Margin | D38: =D36-D37 | E38: =E36-E37 | F38: =F36-F37 | G38: =G36-G37 | H38: =H36-H37 | I38: =I36-I37 | J38: =J36-J37 | K38: =K36-K37 | ... O38: =O36-O37 | P38: =SUM(D38:O38) | Q38: =IF(P36=0,0,P38/P36) | T38: t Consultancy as a Service based upon 25% of new users
B40: Real Estate | C40: =C14 | T40: t ABM Build- Marketing Insights
C41: Licences Sold | D41: 260 | E41: 275 | F41: 300 | G41: 325 | H41: 325 | I41: 360 | J41: 375 | K41: 380 | L41: 385 | M41: 390 | N41: 400 | O41: 400 | P41: =O41 | S41: 0.03
D42: =D41*$S$41 | E42: =E41*$S$41
C43: Total Sales | D43: =(D41-D42)*$D$14 | E43: =(E41-E42)*$D$14 | F43: =F41*$D$14 | G43: =G41*$D$14 | H43: =H41*$D$14 | I43: =I41*$D$14 | J43: =J41*$D$14 | K43: =K41*$D$14 | L43: =L41*$D$14 | M43: =M41*$D$14 | ... O43: =O41*$D$14 | P43: =SUM(D43:O43) | Q43: =(Q44+Q45)
C44: Total COGS | D44: =D41*$E$14 | E44: =E41*$E$14 | F44: =F41*$E$14 | G44: =G41*$E$14 | H44: =H41*$E$14 | I44: =I41*$E$14 | J44: =J41*$E$14 | K44: =K41*$E$14 | ... O44: =O41*$E$14 | P44: =SUM(D44:O44) | Q44: =IF(P43=0,0,P44/P43)
C45: Total Margin | D45: =D43-D44 | E45: =E43-E44 | F45: =F43-F44 | G45: =G43-G44 | H45: =H43-H44 | I45: =I43-I44 | J45: =J43-J44 | K45: =K43-K44 | ... O45: =O43-O44 | P45: =SUM(D45:O45) | Q45: =IF(P43=0,0,P45/P43)
C47: =C15
...

Sheet Revenue 2027
C3: 2027 | D3: Pricing
C4: Offerings and Distribution | D4: Price | E4: COGS | F4: Margin Per Subscription
C5: Administrative | H5: Growth Model
C6: Configuration | D6: 250 | E6: 50 | F6: =D6-E6
C7: On-Boarding- Administrator | D7: 500 | E7: 100 | F7: =D7-E7
C8: On-Boarding Users | D8: 500 | E8: 100 | F8: =D8-E8
C9: Import | D9: ='Pricing Calcuator'!D86 | E9: 600 | F9: =D9-E9
C10: Support | D10: 100 | E10: 50 | F10: =D10-E10
C11: Industry Break Down | E11: ='COGS Analysis'!D18
C12: Hospitality | D12: 250 | E12: ='Revenue 2030'!Q210 | F12: =D12-E12
C13: Hospitality- Reseller | D13: 100 | E13: ='Revenue 2030'!$Q$210 | F13: =D13-E13
C14: Real Estate Development | D14: 400 | E14: ='Revenue 2030'!$Q$210 | F14: =D14-E14
C15: Real Estate Development- Reseller | D15: 250 | E15: ='Revenue 2030'!$Q$210 | F15: =D15-E15
C16: Pharma | D16: 400 | E16: ='Revenue 2030'!$Q$210 | F16: =D16-E16
C17: Pharma- Reseller | D17: 250 | E17: ='Revenue 2030'!$Q$210 | F17: =D17-E17
C18: Start up - Small Firms | D18: 200 | E18: ='Revenue 2030'!$Q$210 | F18: =D18-E18
C19: Start up Reseller | D19: 100 | E19: ='Revenue 2030'!$Q$210 | F19: =D19-E19
C20: Training / Consultancy Training as a Service
C21: Thought Library | D21: 50 | E21: 25 | F21: =D21-E21
C22: Consultancy Services | D22: 225 | E22: 125 | F22: =D22-E22
C24: Segments | D24: January | E24: February | F24: March | G24: April | H24: May | I24: June | J24: July | K24: August | L24: September | M24: October | N24: November | O24: December | P24: Annual Totals | Q24: Profit Margin | R24: Profit margin comparison | S24: Churn
B26: Hospitality | C26: =C12 | T26: Assumptions
C27: Licences Sold | D27: 500 | E27: 525 | F27: 540 | G27: 600 | H27: 625 | I27: 680 | J27: 700 | K27: 725 | L27: 725 | M27: 725 | N27: 725 | O27: 750 | P27: =O27 | S27: 0.03
D28: =D27*$S$27 | E28: =E27*$S$27 | F28: =F27*$S$27 | G28: =G27*$S$27 | H28: =H27*$S$27 | I28: =I27*$S$27 | J28: =J27*$S$27 | K28: =K27*$S$27 | ... O28: =O27*$S$27
C29: Total Sales | D29: =(D27-D28)*$D$12 | E29: =(E27-E28)*$D$12 | F29: =(F27-F28)*$D$12 | G29: =(G27-G28)*$D$12 | H29: =(H27-H28)*$D$12 | I29: =(I27-I28)*$D$12 | J29: =(J27-J28)*$D$12 | K29: =(K27-K28)*$D$12 | ... O29: =(O27-O28)*$D$12 | P29: =SUM(D29:O29) | Q29: =(Q30+Q31)
C30: Total COGS | D30: =D27*$E$12 | E30: =E27*$E$12 | F30: =F27*$E$12 | G30: =G27*$E$12 | H30: =H27*$E$12 | I30: =I27*$E$12 | J30: =J27*$E$12 | K30: =K27*$E$12 | ... O30: =O27*$E$12 | P30: =SUM(D30:O30) | Q30: =IF(P29=0,0,P30/P29) | T30: t Additional sales person added to focus on Start ups and Pharma
C31: Total Margin | D31: =D29-D30 | E31: =E29-E30 | F31: =F29-F30 | G31: =G29-G30 | H31: =H29-H30 | I31: =I29-I30 | J31: =J29-J30 | K31: =K29-K30 | ... O31: =O29-O30 | P31: =SUM(D31:O31) | Q31: =IF(P29=0,0,P31/P29)
T32: t Thought library usage is based on 35% of new users purchasing the thought library access
C33: =C13
C34: Licences Sold | D34: 210 | E34: 450 | F34: 465 | G34: 480 | H34: 480 | I34: 500 | J34: 425 | K34: 425 | L34: 450 | M34: 460 | N34: 470 | O34: 470 | P34: =O34 | S34: 0.03 | T34: t Consultancy as a Service based upon 25% of new users
D35: =D34*$S$34 | E35: =E34*$S$34 | F35: =F34*$S$34 | G35: =G34*$S$34 | H35: =H34*$S$34 | I35: =I34*$S$34 | J35: =J34*$S$34 | K35: =K34*$S$34 | ... O35: =O34*$S$34
C36: Total Sales | D36: =(D34-D35)*$D$13 | E36: =(E34-E35)*$D$13 | F36: =(F34-F35)*$D$13 | G36: =(G34-G35)*$D$13 | H36: =(H34-H35)*$D$13 | I36: =(I34-I35)*$D$13 | J36: =(J34-J35)*$D$13 | K36: =(K34-K35)*$D$13 | ... O36: =(O34-O35)*$D$13 | P36: =SUM(D36:O36) | Q36: =(Q37+Q38)
C37: Total COGS | D37: =D34*$E$13 | E37: =E34*$E$13 | F37: =F34*$E$13 | G37: =G34*$E$13 | H37: =H34*$E$13 | I37: =I34*$E$13 | J37: =J34*$E$13 | K37: =K34*$E$13 | ... O37: =O34*$E$13 | P37: =SUM(D37:O37) | Q37: =IF(P36=0,0,P37/P36) | T37: t Sales Person added for Life Sciences / Pharma
C38: Total Margin | D38: =D36-D37 | E38: =E36-E37 | F38: =F36-F37 | G38: =G36-G37 | H38: =H36-H37 | I38: =I36-I37 | J38: =J36-J37 | K38: =K36-K37 | ... O38: =O36-O37 | P38: =SUM(D38:O38) | Q38: =IF(P36=0,0,P38/P36)
T39: t ABM Benefit Realized
B40: Real Estate | C40: =C14
C41: Licences Sold | D41: 400 | E41: 500 | F41: 510 | G41: 530 | H41: 540 | I41: 570 | J41: 580 | K41: 570 | L41: 600 | M41: 625 | N41: 625 | O41: 625 | P41: =O41 | S41: 0.03
D42: =D41*$S$41 | E42: =E41*$S$41 | F42: =F41*$S$41 | G42: =G41*$S$41 | H42: =H41*$S$41 | I42: =I41*$S$41 | J42: =J41*$S$41 | K42: =K41*$S$41 | ... O42: =O41*$S$41
C43: Total Sales | D43: =(D41-D42)*$D$14 | E43: =(E41-E42)*$D$14 | F43: =(F41-F42)*$D$14 | G43: =(G41-G42)*$D$14 | H43: =(H41-H42)*$D$14 | I43: =(I41-I42)*$D$14 | J43: =(J41-J42)*$D$14 | K43: =(K41-K42)*$D$14 | ... O43: =(O41-O42)*$D$14 | P43: =SUM(D43:O43) | Q43: =(Q44+Q45)
C44: Total COGS | D44: =D41*$E$14 | E44: =E41*$E$14 | F44: =F41*$E$14 | G44: =G41*$E$14 | H44: =H41*$E$14 | I44: =I41*$E$14 | J44: =J41*$E$14 | K44: =K41*$E$14 | ... O44: =O41*$E$14 | P44: =SUM(D44:O44) | Q44: =IF(P43=0,0,P44/P43)
...

Sheet Revenue 2028
C3: 2028 | D3: Pricing
C4: Offerings and Distribution | D4: Price | E4: COGS | F4: Margin Per Subscription
C5: Administrative
C6: Configuration | D6: 250 | E6: 50 | F6: =D6-E6
C7: On-Boarding- Administrator | D7: 500 | E7: 100 | F7: =D7-E7
C8: On-Boarding Users | D8: 500 | E8: 100 | F8: =D8-E8
C9: Import | D9: ='Pricing Calcuator'!D86 | E9: 600 | F9: =D9-E9
C10: Support | D10: 100 | E10: 50 | F10: =D10-E10
C11: Industry Break Down | E11: ='COGS Analysis'!D18
C12: Hospitality | D12: 250 | E12: ='Revenue 2030'!$Q$210 | F12: =D12-E12
C13: Hospitality- Reseller | D13: 100 | E13: ='Revenue 2030'!$Q$210 | F13: =D13-E13
C14: Real Estate Development | D14: 450 | E14: ='Revenue 2030'!$Q$210 | F14: =D14-E14
C15: Real Estate Development- Reseller | D15: 250 | E15: ='Revenue 2030'!$Q$210 | F15: =D15-E15
C16: Pharma | D16: 400 | E16: ='Revenue 2030'!$Q$210 | F16: =D16-E16
C17: Pharma- Reseller | D17: 250 | E17: ='Revenue 2030'!$Q$210 | F17: =D17-E17
C18: Start up - Small Firms | D18: 200 | E18: ='Revenue 2030'!$Q$210 | F18: =D18-E18
C19: Start up Reseller | D19: 100 | E19: ='Revenue 2030'!$Q$210 | F19: =D19-E19
C20: Training / Consultancy Training as a Service
C21: Thought Library | D21: 50 | E21: 25 | F21: =D21-E21
C22: Consultancy Services | D22: 225 | E22: 125 | F22: =D22-E22
C24: Segments | D24: January | E24: February | F24: March | G24: April | H24: May | I24: June | J24: July | K24: August | L24: September | M24: October | N24: November | O24: December | P24: Annual Totals | Q24: Profit Margin | R24: Profit margin comparison | S24: CHURN
B26: Hospitality | C26: =C12 | T26: Assumptions
C27: Licences Sold | D27: 750 | E27: 770 | F27: 790 | G27: 800 | H27: 1000 | I27: 1000 | J27: 1100 | K27: 1200 | L27: 1225 | M27: 1250 | N27: 1250 | O27: 1250 | P27: =O27 | S27: 0.03
D28: =D27*$S$27 | E28: =E27*$S$27 | F28: =F27*$S$27 | G28: =G27*$S$27 | H28: =H27*$S$27 | I28: =I27*$S$27 | J28: =J27*$S$27 | K28: =K27*$S$27 | ... O28: =O27*$S$27
C29: Total Sales | D29: =(D27-D28)*$D$12 | E29: =(E27-E28)*$D$12 | F29: =(F27-F28)*$D$12 | G29: =(G27-G28)*$D$12 | H29: =(H27-H28)*$D$12 | I29: =(I27-I28)*$D$12 | J29: =(J27-J28)*$D$12 | K29: =(K27-K28)*$D$12 | ... O29: =(O27-O28)*$D$12 | P29: =SUM(D29:O29) | Q29: =(Q30+Q31)
C30: Total COGS | D30: =D27*$E$12 | E30: =E27*$E$12 | F30: =F27*$E$12 | G30: =G27*$E$12 | H30: =H27*$E$12 | I30: =I27*$E$12 | J30: =J27*$E$12 | K30: =K27*$E$12 | ... O30: =O27*$E$12 | P30: =SUM(D30:O30) | Q30: =IF(P29=0,0,P30/P29)
C31: Total Margin | D31: =D29-D30 | E31: =E29-E30 | F31: =F29-F30 | G31: =G29-G30 | H31: =H29-H30 | I31: =I29-I30 | J31: =J29-J30 | K31: =K29-K30 | ... O31: =O29-O30 | P31: =SUM(D31:O31) | Q31: =IF(P29=0,0,P31/P29)
C33: =C13
C34: Licences Sold | D34: 470 | E34: 500 | F34: 525 | G34: 530 | H34: 535 | I34: 540 | J34: 550 | K34: 560 | L34: 570 | M34: 590 | N34: 600 | O34: 600 | P34: =O34 | S34: 0.03
D35: =D34*$S$34 | E35: =E34*$S$34 | F35: =F34*$S$34 | G35: =G34*$S$34 | H35: =H34*$S$34 | I35: =I34*$S$34 | J35: =J34*$S$34 | K35: =K34*$S$34 | ... O35: =O34*$S$34
C36: Total Sales | D36: =(D34-D35)*$D$13 | E36: =(E34-E35)*$D$13 | F36: =(F34-F35)*$D$13 | G36: =(G34-G35)*$D$13 | H36: =(H34-H35)*$D$13 | I36: =(I34-I35)*$D$13 | J36: =(J34-J35)*$D$13 | K36: =(K34-K35)*$D$13 | ... O36: =(O34-O35)*$D$13 | P36: =SUM(D36:O36) | Q36: =(Q37+Q38)
C37: Total COGS | D37: =D34*$E$13 | E37: =E34*$E$13 | F37: =F34*$E$13 | G37: =G34*$E$13 | H37: =H34*$E$13 | I37: =I34*$E$13 | J37: =J34*$E$13 | K37: =K34*$E$13 | ... O37: =O34*$E$13 | P37: =SUM(D37:O37) | Q37: =IF(P36=0,0,P37/P36)
C38: Total Margin | D38: =D36-D37 | E38: =E36-E37 | F38: =F36-F37 | G38: =G36-G37 | H38: =H36-H37 | I38: =I36-I37 | J38: =J36-J37 | K38: =K36-K37 | ... O38: =O36-O37 | P38: =SUM(D38:O38) | Q38: =IF(P36=0,0,P38/P36)
B40: Real Estate | C40: =C14
C41: Licences Sold | D41: 625 | E41: 625 | F41: 630 | G41: 630 | H41: 630 | I41: 630 | J41: 650 | K41: 650 | L41: 660 | M41: 660 | N41: 660 | O41: 660 | P41: =O41 | S41: 0.03
D42: =D41*$S$41 | E42: =E41*$S$41 | F42: =F41*$S$41 | G42: =G41*$S$41 | H42: =H41*$S$41 | I42: =I41*$S$41 | J42: =J41*$S$41 | K42: =K41*$S$41 | ... O42: =O41*$S$41
C43: Total Sales | D43: =(D41-D42)*$D$14 | E43: =(E41-E42)*$D$14 | F43: =(F41-F42)*$D$14 | G43: =(G41-G42)*$D$14 | H43: =(H41-H42)*$D$14 | I43: =(I41-I42)*$D$14 | J43: =(J41-J42)*$D$14 | K43: =(K41-K42)*$D$14 | ... O43: =(O41-O42)*$D$14 | P43: =SUM(D43:O43) | Q43: =(Q44+Q45)
C44: Total COGS | D44: =D41*$E$14 | E44: =E41*$E$14 | F44: =F41*$E$14 | G44: =G41*$E$14 | H44: =H41*$E$14 | I44: =I41*$E$14 | J44: =J41*$E$14 | K44: =K41*$E$14 | ... O44: =O41*$E$14 | P44: =SUM(D44:O44) | Q44: =IF(P43=0,0,P44/P43)
C45: Total Margin | D45: =D43-D44 | E45: =E43-E44 | F45: =F43-F44 | G45: =G43-G44 | H45: =H43-H44 | I45: =I43-I44 | J45: =J43-J44 | K45: =K43-K44 | ... O45: =O43-O44 | P45: =SUM(D45:O45) | Q45: =IF(P43=0,0,P45/P43)
C47: =C15
...

Sheet Revenue 2029
C3: 2029 | D3: Pricing
C4: Offerings and Distribution | D4: Price | E4: COGS | F4: Margin Per Subscription
C5: Administrative
C6: Configuration | D6: 250 | E6: 50 | F6: =D6-E6
C7: On-Boarding- Administrator | D7: ='Pricing Calcuator'!D79 | E7: 100 | F7: =D7-E7
C8: On-Boarding Users | D8: ='Pricing Calcuator'!D82 | E8: 100 | F8: =D8-E8
C9: Import | D9: ='Pricing Calcuator'!D86 | E9: 600 | F9: =D9-E9
C10: Support | D10: 100 | E10: ='COGS Analysis'!D18 | F10: =D10-E10
C11: Industry Break Down | E11: ='COGS Analysis'!D18
C12: ='Pricing Calcuator'!C7 | D12: ='Pricing Calcuator'!D7 | E12: ='Revenue 2030'!$Q$210 | F12: =D12-E12
C13: ='Pricing Calcuator'!C8 | D13: 200 | E13: ='Revenue 2030'!$Q$210 | F13: =D13-E13
C14: ='Pricing Calcuator'!C9 | D14: ='Pricing Calcuator'!D9 | E14: ='Revenue 2030'!$Q$210 | F14: =D14-E14
C15: ='Pricing Calcuator'!C10 | D15: ='Pricing Calcuator'!D10 | E15: ='Revenue 2030'!$Q$210 | F15: =D15-E15
C16: ='Pricing Calcuator'!C11 | D16: ='Pricing Calcuator'!D11 | E16: ='Revenue 2030'!$Q$210 | F16: =D16-E16
C17: ='Pricing Calcuator'!C12 | D17: ='Pricing Calcuator'!D12 | E17: ='Revenue 2030'!$Q$210 | F17: =D17-E17
C18: ='Pricing Calcuator'!C13 | D18: ='Pricing Calcuator'!D13 | E18: ='Revenue 2030'!$Q$210 | F18: =D18-E18
C19: ='Pricing Calcuator'!C14 | D19: ='Pricing Calcuator'!D14 | E19: ='Revenue 2030'!$Q$210 | F19: =D19-E19
C20: Training / Consultancy Training as a Service
C21: Thought Library | D21: ='Pricing Calcuator'!D90 | E21: 25 | F21: =D21-E21
C22: Consultancy Services | D22: ='Pricing Calcuator'!D93 | E22: 125 | F22: =D22-E22
C24: Segments | D24: January | E24: February | F24: March | G24: April | H24: May | I24: June | J24: July | K24: August | L24: September | M24: October | N24: November | O24: December | P24: Annual Totals | Q24: Profit Margin | R24: Profit margin comparison | S24: CHURN
B26: Hospitality | C26: =C12
C27: Licenses Sold | D27: 1250 | E27: 1280 | F27: 1325 | G27: 1378 | H27: 1400 | I27: 1450 | J27: 1475 | K27: 1500 | L27: 1525 | M27: 1530 | N27: 1550 | O27: 1560 | P27: =O27 | S27: 0.03 | T27: Assumptions
D28: =D27*$S$27 | E28: =E27*$S$27 | F28: =F27*$S$27 | G28: =G27*$S$27 | H28: =H27*$S$27 | I28: =I27*$S$27 | J28: =J27*$S$27 | K28: =K27*$S$27 | ... O28: =O27*$S$27
C29: Total Sales | D29: =(D27-D28)*$D$12 | E29: =(E27-E28)*$D$12 | F29: =(F27-F28)*$D$12 | G29: =(G27-G28)*$D$12 | H29: =(H27-H28)*$D$12 | I29: =(I27-I28)*$D$12 | J29: =(J27-J28)*$D$12 | K29: =(K27-K28)*$D$12 | ... O29: =(O27-O28)*$D$12 | P29: =SUM(D29:O29) | Q29: =(Q30+Q31)
C30: Total COGS | D30: =D27*$E$12 | E30: =E27*$E$12 | F30: =F27*$E$12 | G30: =G27*$E$12 | H30: =H27*$E$12 | I30: =I27*$E$12 | J30: =J27*$E$12 | K30: =K27*$E$12 | ... O30: =O27*$E$12 | P30: =SUM(D30:O30) | Q30: =IF(P29=0,0,P30/P29) | T30: t Additonal Sales person for flex
C31: Total Margin | D31: =D29-D30 | E31: =E29-E30 | F31: =F29-F30 | G31: =G29-G30 | H31: =H29-H30 | I31: =I29-I30 | J31: =J29-J30 | K31: =K29-K30 | ... O31: =O29-O30 | P31: =SUM(D31:O31) | Q31: =IF(P29=0,0,P31/P29)
C33: =C13
C34: Licences Sold | D34: 600 | E34: 610 | F34: 625 | G34: 675 | H34: 685 | I34: 690 | J34: 700 | K34: 715 | L34: 725 | M34: 735 | N34: 745 | O34: 750 | P34: =O34 | S34: 0.03
D35: =D34*$S$27 | E35: =E34*$S$27 | F35: =F34*$S$27 | G35: =G34*$S$27 | H35: =H34*$S$27 | I35: =I34*$S$27 | J35: =J34*$S$27 | K35: =K34*$S$27 | ... O35: =O34*$S$27
C36: Total Sales | D36: =(D34-D35)*$D$13 | E36: =(E34-E35)*$D$13 | F36: =(F34-F35)*$D$13 | G36: =(G34-G35)*$D$13 | H36: =(H34-H35)*$D$13 | I36: =(I34-I35)*$D$13 | J36: =(J34-J35)*$D$13 | K36: =(K34-K35)*$D$13 | ... O36: =(O34-O35)*$D$13 | P36: =SUM(D36:O36) | Q36: =(Q37+Q38)
C37: Total COGS | D37: =D34*$E$13 | E37: =E34*$E$13 | F37: =F34*$E$13 | G37: =G34*$E$13 | H37: =H34*$E$13 | I37: =I34*$E$13 | J37: =J34*$E$13 | K37: =K34*$E$13 | ... O37: =O34*$E$13 | P37: =SUM(D37:O37) | Q37: =IF(P36=0,0,P37/P36)
C38: Total Margin | D38: =D36-D37 | E38: =E36-E37 | F38: =F36-F37 | G38: =G36-G37 | H38: =H36-H37 | I38: =I36-I37 | J38: =J36-J37 | K38: =K36-K37 | ... O38: =O36-O37 | P38: =SUM(D38:O38) | Q38: =IF(P36=0,0,P38/P36)
B40: Real Estate | C40: =C14
C41: Licences Sold | D41: 660 | E41: 670 | F41: 680 | G41: 690 | H41: 700 | I41: 710 | J41: 720 | K41: 730 | L41: 740 | M41: 750 | N41: 750 | O41: 750 | P41: =O41 | S41: 0.03
D42: =D41*S41 | E42: =E41*$S$41 | F42: =F41*$S$41 | G42: =G41*$S$41 | H42: =H41*$S$41 | I42: =I41*$S$41 | J42: =J41*$S$41 | K42: =K41*$S$41 | L42: =L41*$S$41 | ... O42: =O41*$S$41
C43: Total Sales | D43: =(D41-D42)*$D$14 | E43: =(E41-E42)*$D$14 | F43: =(F41-F42)*$D$14 | G43: =(G41-G42)*$D$14 | H43: =(H41-H42)*$D$14 | I43: =(I41-I42)*$D$14 | J43: =(J41-J42)*$D$14 | K43: =(K41-K42)*$D$14 | ... O43: =(O41-O42)*$D$14 | P43: =SUM(D43:O43) | Q43: =(Q44+Q45)
C44: Total COGS | D44: =D41*$E$14 | E44: =E41*$E$14 | F44: =F41*$E$14 | G44: =G41*$E$14 | H44: =H41*$E$14 | I44: =I41*$E$14 | J44: =J41*$E$14 | K44: =K41*$E$14 | ... O44: =O41*$E$14 | P44: =SUM(D44:O44) | Q44: =IF(P43=0,0,P44/P43)
C45: Total Margin | D45: =D43-D44 | E45: =E43-E44 | F45: =F43-F44 | G45: =G43-G44 | H45: =H43-H44 | I45: =I43-I44 | J45: =J43-J44 | K45: =K43-K44 | ... O45: =O43-O44 | P45: =SUM(D45:O45) | Q45: =IF(P43=0,0,P45/P43)
C47: =C15
...

Sheet Revenue 2030
C3: 2030 | D3: Pricing
C4: Offerings and Distribution | D4: Price | E4: COGS | F4: Margin Per Subscription
C5: Administrative
C6: Configuration | D6: 250 | E6: 50 | F6: =D6-E6
C7: On-Boarding- Administrator | D7: 500 | E7: 100 | F7: =D7-E7
C8: On-Boarding Users | D8: 500 | E8: 100 | F8: =D8-E8
C9: Import | D9: ='Pricing Calcuator'!D86 | E9: 600 | F9: =D9-E9
C10: Support | D10: 100 | E10: 50 | F10: =D10-E10
C11: Industry Break Down | E11: ='COGS Analysis'!D18
C12: Hospitality | D12: 250 | E12: =$Q$210 | F12: =D12-E12
C13: Hospitality- Reseller | D13: 100 | E13: =$Q$210 | F13: =D13-E13
C14: Real Estate Development | D14: 400 | E14: =$Q$210 | F14: =D14-E14
C15: Real Estate Development- Reseller | D15: 200 | E15: =$Q$210 | F15: =D15-E15
C16: Pharma | D16: 450 | E16: =$Q$210 | F16: =D16-E16
C17: Pharma- Reseller | D17: 200 | E17: =$Q$210 | F17: =D17-E17
C18: Start up - Small Firms | D18: 200 | E18: =$Q$210 | F18: =D18-E18
C19: Start up Reseller | D19: 100 | E19: =$Q$210 | F19: =D19-E19
C20: Training / Consultancy Training as a Service
C21: Thought Library | D21: 50 | E21: 25 | F21: =D21-E21
C22: Consultancy Services | D22: 225 | E22: 125 | F22: =D22-E22
C24: Segments | D24: January | E24: February | F24: March | G24: April | H24: May | I24: June | J24: July | K24: August | L24: September | M24: October | N24: November | O24: December | P24: Annual Totals | Q24: Profit Margin | R24: Profit margin comparison | S24: Churn | T24: Assumptions
B26: Hospitality | C26: =C12
C27: Licences Sold | D27: 1580 | E27: 1600 | F27: 1630 | G27: 1650 | H27: 1680 | I27: 1725 | J27: 1775 | K27: 2000 | L27: 2125 | M27: 2180 | N27: 2200 | O27: 2235 | P27: =O27 | S27: 0.03
D28: =D27*$S$27 | E28: =E27*$S$27 | F28: =F27*$S$27 | G28: =G27*$S$27 | H28: =H27*$S$27 | I28: =I27*$S$27 | J28: =J27*$S$27 | K28: =K27*$S$27 | ... O28: =O27*$S$27
C29: Total Sales | D29: =(D27-D28)*$D$12 | E29: =(E27-E28)*$D$12 | F29: =(F27-F28)*$D$12 | G29: =(G27-G28)*$D$12 | H29: =(H27-H28)*$D$12 | I29: =(I27-I28)*$D$12 | J29: =(J27-J28)*$D$12 | K29: =(K27-K28)*$D$12 | ... O29: =(O27-O28)*$D$12 | P29: =SUM(D29:O29) | Q29: =(Q30+Q31)
C30: Total COGS | D30: =D27*$E$12 | E30: =E27*$E$12 | F30: =F27*$E$12 | G30: =G27*$E$12 | H30: =H27*$E$12 | I30: =I27*$E$12 | J30: =J27*$E$12 | K30: =K27*$E$12 | ... O30: =O27*$E$12 | P30: =SUM(D30:O30) | Q30: =IF(P29=0,0,P30/P29)
C31: Total Margin | D31: =D29-D30 | E31: =E29-E30 | F31: =F29-F30 | G31: =G29-G30 | H31: =H29-H30 | I31: =I29-I30 | J31: =J29-J30 | K31: =K29-K30 | ... O31: =O29-O30 | P31: =SUM(D31:O31) | Q31: =IF(P29=0,0,P31/P29)
C33: =C13
C34: Licences Sold | D34: 765 | E34: 765 | F34: 770 | G34: 775 | H34: 780 | I34: 785 | J34: 790 | K34: 795 | L34: 800 | M34: 810 | N34: 810 | O34: 810 | P34: =O34 | S34: 0.03
D35: =D34*$S$34 | E35: =E34*$S$34 | F35: =F34*$S$34 | G35: =G34*$S$34 | H35: =H34*$S$34 | I35: =I34*$S$34 | J35: =J34*$S$34 | K35: =K34*$S$34 | ... O35: =O34*$S$34
C36: Total Sales | D36: =(D34-D35)*$D$13 | E36: =(E34-E35)*$D$13 | F36: =(F34-F35)*$D$13 | G36: =(G34-G35)*$D$13 | H36: =(H34-H35)*$D$13 | I36: =(I34-I35)*$D$13 | J36: =(J34-J35)*$D$13 | K36: =(K34-K35)*$D$13 | ... O36: =(O34-O35)*$D$13 | P36: =SUM(D36:O36) | Q36: =(Q37+Q38)
C37: Total COGS | D37: =D34*$E$13 | E37: =E34*$E$13 | F37: =F34*$E$13 | G37: =G34*$E$13 | H37: =H34*$E$13 | I37: =I34*$E$13 | J37: =J34*$E$13 | K37: =K34*$E$13 | ... O37: =O34*$E$13 | P37: =SUM(D37:O37) | Q37: =IF(P36=0,0,P37/P36)
C38: Total Margin | D38: =D36-D37 | E38: =E36-E37 | F38: =F36-F37 | G38: =G36-G37 | H38: =H36-H37 | I38: =I36-I37 | J38: =J36-J37 | K38: =K36-K37 | ... O38: =O36-O37 | P38: =SUM(D38:O38) | Q38: =IF(P36=0,0,P38/P36)
B40: Real Estate | C40: =C14
C41: Licences Sold | D41: 760 | E41: 775 | F41: 780 | G41: 785 | H41: 790 | I41: 800 | J41: 815 | K41: 825 | L41: 830 | M41: 835 | N41: 840 | O41: 845 | P41: =O41 | S41: 0.03
D42: =D41*$S$41 | E42: =E41*$S$41 | F42: =F41*$S$41 | G42: =G41*$S$41 | H42: =H41*$S$41 | I42: =I41*$S$41 | J42: =J41*$S$41 | K42: =K41*$S$41 | ... O42: =O41*$S$41
C43: Total Sales | D43: =(D41-D42)*$D$14 | E43: =(E41-E42)*$D$14 | F43: =(F41-F42)*$D$14 | G43: =(G41-G42)*$D$14 | H43: =(H41-H42)*$D$14 | I43: =(I41-I42)*$D$14 | J43: =(J41-J42)*$D$14 | K43: =(K41-K42)*$D$14 | ... O43: =(O41-O42)*$D$14 | P43: =SUM(D43:O43) | Q43: =(Q44+Q45)
C44: Total COGS | D44: =D41*$E$14 | E44: =E41*$E$14 | F44: =F41*$E$14 | G44: =G41*$E$14 | H44: =H41*$E$14 | I44: =I41*$E$14 | J44: =J41*$E$14 | K44: =K41*$E$14 | ... O44: =O41*$E$14 | P44: =SUM(D44:O44) | Q44: =IF(P43=0,0,P44/P43)
C45: Total Margin | D45: =D43-D44 | E45: =E43-E44 | F45: =F43-F44 | G45: =G43-G44 | H45: =H43-H44 | I45: =I43-I44 | J45: =J43-J44 | K45: =K43-K44 | ... O45: =O43-O44 | P45: =SUM(D45:O45) | Q45: =IF(P43=0,0,P45/P43)
C47: =C15
...

Sheet COGS Analysis
C3: PRODUCT | D3: Vendor | E3: Plan Name | F3: Cost Link | G3: Cost Unit | H3: Cost Unit Number | I3: Cost Per Month | K3: Annual Cost (Unit X Month) | L3: 2
C4: Support | K4: =Table13[[#This Row],[Cost Per Month]]*12*Table13[[#This Row],[Cost Unit Number]]
B5: By Customer Support | C5: E-mail & Chat | D5: FreshWorks | E5: FreshChat - Sprout Plan (free) | F5: Support Desk Pricing | G5: per license; 5000 bot | H5: 1 | I5: 69 | K5: =Table13[[#This Row],[Cost Per Month]]*12*Table13[[#This Row],[Cost Unit Number]]
C6: OMNICHANNEL; Ticketing | D6: FreshWorks | E6: FreshDesk - Estate Omnichannel | F6: Fresh Desk Omni Channel | G6: per user | H6: 1 | I6: 79 | K6: =Table13[[#This Row],[Cost Per Month]]*12*Table13[[#This Row],[Cost Unit Number]]
C7: SUPPORT DESK | D7: Zoom | G7: per user | H7: 3 | I7: 149 | K7: =Table13[[#This Row],[Cost Per Month]]*Table13[[#This Row],[Cost Unit Number]]
D8: phone | F8: Freshworks | G8: per user | H8: 3 | I8: 3 | K8: =Table13[[#This Row],[Cost Per Month]]*12*Table13[[#This Row],[Cost Unit Number]]
B9: BY LICENCE | C9: Data Integration | D9: hConnect | F9: https://hconnect.io/ | G9: per license | H9: 12 | I9: 600 | K9: 0
B10: Back Office | C10: Hosting | D10: AWS | G10: cost per month | H10: 12 | I10: 2000 | K10: =Table13[[#This Row],[Cost Per Month]]*Table13[[#This Row],[Cost Unit Number]]
C11: Billing (SAS recurring management software) | D11: Chargebee | E11: Chargebee | F11: Chargebee Pricing | G11: includes USD 600K/yr revenue 0.6% of overage revenue | H11: 1 | I11: 249 | K11: =Table13[[#This Row],[Cost Per Month]]*12*Table13[[#This Row],[Cost Unit Number]]
C12: Total | K12: =SUBTOTAL(109,Table13[Annual Cost (Unit X Month)])
D14: 1
C15: TOTAL TECHNOLOGY Service & Operations costs annual | D15: =Table13[[#Totals],[Annual Cost (Unit X Month)]]
C16: Cost Per Month | D16: =D15/12

Sheet Salaries & Wages
C4: Forecast | Q4: Forecast | AE4: Forecast | AS4: Forecast | BG4: Forecast | BU4: Forecast
C5: 2025 | O5: 2025 | Q5: 2026 | AC5: 2026 | AE5: 2027 | AQ5: 2027 | AS5: 2028 | BE5: 2028 | BG5: 2029 | BS5: 2029 | BU5: 2030 | CG5: 2030
C6: 45658 | D6: 45689 | E6: 45717 | F6: 45748 | G6: 45778 | H6: 45809 | I6: 45839 | J6: 45870 | K6: 45901 | L6: 45931 | M6: 45962 | N6: 45992 | O6: Total | P6: 2025 Head Count | Q6: 46023 | R6: 46054 | S6: 46082 | T6: 46113 | U6: 46143 | V6: 46174 | W6: 46204 | X6: 46235 | Y6: 46266 | Z6: 46296 | AA6: 46327 | AB6: 46357 | AC6: Total | AD6: 2026 Head Count | AE6: 46388 | AF6: 46419 | AG6: 46447 | AH6: 46478 | AI6: 46508 | AJ6: 46539 | AK6: 46569 | AL6: 46600 | AM6: 46631 | AN6: 46661 | AO6: 46692 | AP6: 46722 | AQ6: Total | AR6: 2027 Head Count | AS6: 46753 | AT6: 46784 | AU6: 46813 | AV6: 46844 | AW6: 5/=2028 | AX6: 46905 | AY6: 46935 | AZ6: 46966 | BA6: 46997 | BB6: 47027 | BC6: 47058 | BD6: 47088 | BE6: Total | BF6: 2028 Head Count | BG6: 47119 | BH6: 47150 | BI6: 47178 | BJ6: 47209 | BK6: 47239 | BL6: 47270 | BM6: 47300 | BN6: 47331 | BO6: 47362 | BP6: 47392 | BQ6: 47423 | BR6: 47453 | BS6: Total | BT6: 2029 Head Count | BU6: 47484 | BV6: 44958 | BW6: 47543 | BX6: 47574 | BY6: 47604 | BZ6: 6/20230 | CA6: 47665 | CB6: 47696 | CC6: 47727 | CD6: 47757 | CE6: 47788 | CF6: 47818 | CG6: Total | CH6: 2030 Head Count
A7: Salaries And Wages :
A8: CEO | C8: 5000 | D8: =$C$8 | E8: =$C$8 | F8: =$C$8 | G8: =$C$8 | H8: =$C$8 | I8: =$C$8 | J8: =$C$8 | K8: =$C$8 | ... N8: =$C$8 | O8: =SUM(C8:N8) | P8: 0.5 | Q8: 6500 | R8: =$Q$8 | S8: =$Q$8 | T8: =$Q$8 | U8: =$Q$8 | V8: =$Q$8 | W8: =$Q$8 | X8: =$Q$8 | Y8: =$Q$8 | ... AB8: =$Q$8 | AC8: =SUM(Q8:AB8) | AD8: 1 | AE8: 10000 | AF8: =$AE$8 | AG8: =$AE$8 | AH8: =$AE$8 | AI8: =$AE$8 | AJ8: =$AE$8 | AK8: =$AE$8 | AL8: =$AE$8 | AM8: =$AE$8 | ... AP8: =$AE$8 | AQ8: =SUM(AE8:AP8) | AR8: 1 | AS8: 10000 | AT8: =$AS$8 | AU8: =$AS$8 | AV8: =$AS$8 | AW8: =$AS$8 | AX8: =$AS$8 | AY8: =$AS$8 | AZ8: =$AS$8 | BA8: =$AS$8 | ... BD8: =$AS$8 | BE8: =SUM(AS8:BD8) | BF8: 1 | BG8: 12000 | BH8: =$BG$8 | BI8: =$BG$8 | BJ8: =$BG$8 | BK8: =$BG$8 | BL8: =$BG$8 | BM8: =$BG$8 | BN8: =$BG$8 | BO8: =$BG$8 | ... BR8: =$BG$8 | BS8: =SUM(BG8:BR8) | BT8: 1 | BU8: 12000 | BV8: =$BG$8 | BW8: =$BG$8 | BX8: =$BG$8 | BY8: =$BG$8 | BZ8: =$BG$8 | CA8: =$BG$8 | CB8: =$BG$8 | CC8: =$BG$8 | ... CF8: =$BG$8 | CG8: =SUM(BU8:CF8) | CH8: 1
A9: CFO Accting | C9: 0 | D9: =$C$9 | E9: =$C$9 | F9: =$C$9 | G9: =$C$9 | H9: =$C$9 | I9: =$C$9 | J9: =$C$9 | K9: =$C$9 | ... N9: =$C$9 | O9: =SUM(J9:N9) | Q9: 0 | R9: 0 | S9: 0 | T9: 0 | U9: 0 | V9: 0 | W9: 0 | X9: 0 | Y9: 0 | Z9: 0 | AA9: 0 | AB9: 0 | AC9: =SUM(Q9:AB9) | AE9: 0 | AF9: =$AE$9 | AG9: =$AE$9 | AH9: =$AE$9 | AI9: =$AE$9 | AJ9: =$AE$9 | AK9: =$AE$9 | AL9: =$AE$9 | AM9: =$AE$9 | ... AP9: =$AE$9 | AQ9: =SUM(AE9:AP9) | AR9: 1 | AS9: 6000 | AT9: 6000 | AU9: 6000 | AV9: 6000 | AW9: 6000 | AX9: 6000 | AY9: 6000 | AZ9: 6000 | BA9: 6000 | BB9: 6000 | BC9: 6000 | BD9: 6000 | BE9: =SUM(AS9:BD9) | BF9: 1 | BG9: 6000 | BH9: =$BG$9 | BI9: =$BG$9 | BJ9: =$BG$9 | BK9: =$BG$9 | BL9: =$BG$9 | BM9: =$BG$9 | BN9: =$BG$9 | BO9: =$BG$9 | ... BR9: =$BG$9 | BS9: =SUM(BG9:BR9) | BT9: 1 | BU9: 6000 | BV9: =$BU$9 | BW9: =$BU$9 | BX9: =$BU$9 | BY9: =$BU$9 | BZ9: =$BU$9 | CA9: =$BU$9 | CB9: =$BU$9 | CC9: =$BU$9 | ... CF9: =$BU$9 | CG9: =SUM(BU9:CF9) | CH9: 1
A10: Product /Technology | C10: 10000 | D10: =C10 | E10: =D10 | F10: =E10 | G10: =F10 | H10: =G10 | I10: =H10 | J10: =I10 | K10: =J10 | ... N10: =M10 | O10: =SUM(C10:N10) | P10: 0.5 | Q10: 6500 | R10: 6500 | S10: 6500 | T10: 6500 | U10: 6500 | V10: 6500 | W10: 6500 | X10: 6500 | Y10: 6500 | Z10: 6500 | AA10: 6500 | AB10: 6500 | AC10: =SUM(Q10:AB10) | AD10: 1 | AE10: 7500 | AF10: =$AE$10 | AG10: 7500 | AH10: 7500 | AI10: 7500 | AJ10: 7500 | AK10: 7500 | AL10: 7500 | AM10: 7500 | AN10: 7500 | AO10: 7500 | AP10: 7500 | AQ10: =SUM(AE10:AP10) | AR10: 1 | AS10: 7000 | AT10: 7000 | AU10: 7000 | AV10: 7000 | AW10: 7000 | AX10: 7000 | AY10: 7000 | AZ10: 7000 | BA10: 7000 | BB10: 7000 | BC10: 7000 | BD10: 7000 | BE10: =SUM(AS10:BD10) | BF10: 1 | BG10: 7000 | BH10: =$BG$10 | BI10: =$BG$10 | BJ10: =$BG$10 | BK10: =$BG$10 | BL10: =$BG$10 | BM10: =$BG$10 | BN10: =$BG$10 | BO10: =$BG$10 | ... BR10: =$BG$10 | BS10: =SUM(BG10:BR10) | BT10: 1 | BU10: 7000 | BV10: =$BU$10 | BW10: =$BU$10 | BX10: =$BU$10 | BY10: =$BU$10 | BZ10: =$BU$10 | CA10: =$BU$10 | CB10: =$BU$10 | CC10: =$BU$10 | ... CF10: =$BU$10 | CG10: =SUM(BU10:CF10) | CH10: 1
A11: Operations | O11: =SUM(C11:N11)
A12: COO | C12: 3500 | D12: =$C$12 | E12: =$C$12 | F12: =$C$12 | G12: =$C$12 | H12: =$C$12 | I12: =$C$12 | J12: =$C$12 | K12: =$C$12 | ... N12: =$C$12 | O12: =SUM(C12:N12) | P12: 0.5 | Q12: 6500 | R12: =$Q$12 | S12: =$Q$12 | T12: =$Q$12 | U12: =$Q$12 | V12: =$Q$12 | W12: =$Q$12 | X12: =$Q$12 | Y12: =$Q$12 | ... AB12: =$Q$12 | AC12: =SUM(Q12:AB12) | AD12: 1 | AE12: 7500 | AF12: =$AE$12 | AG12: =$AE$12 | AH12: =$AE$12 | AI12: =$AE$12 | AJ12: =$AE$12 | AK12: =$AE$12 | AL12: =$AE$12 | AM12: =$AE$12 | ... AP12: =$AE$12 | AQ12: =SUM(AE12:AP12) | AR12: 1 | AS12: 7500 | AT12: =$AS$12 | AU12: =$AS$12 | AV12: =$AS$12 | AW12: =$AS$12 | AX12: =$AS$12 | AY12: =$AS$12 | AZ12: =$AS$12 | BA12: =$AS$12 | ... BD12: =$AS$12 | BE12: =SUM(AS12:BD12) | BF12: 1 | BG12: 6500 | BH12: =$BG$12 | BI12: =$BG$12 | BJ12: =$BG$12 | BK12: =$BG$12 | BL12: =$BG$12 | BM12: =$BG$12 | BN12: =$BG$12 | BO12: =$BG$12 | ... BR12: =$BG$12 | BS12: =SUM(BG12:BR12) | BT12: 1 | BU12: 6500 | BV12: =$BG$12 | BW12: =$BG$12 | BX12: =$BG$12 | BY12: =$BG$12 | BZ12: =$BG$12 | CA12: =$BG$12 | CB12: =$BG$12 | CC12: =$BG$12 | ... CF12: =$BG$12 | CG12: =SUM(BU12:CF12) | CH12: 1
A13: Customer Success | C13: 0 | D13: 0 | E13: 0 | F13: 0 | G13: 0 | H13: 0 | I13: 0 | J13: 0 | K13: 0 | L13: 0 | M13: 0 | N13: 0 | O13: =SUM(C13:N13) | Q13: 3000 | R13: =$Q$13 | S13: =$Q$13 | T13: =$Q$13 | U13: =$Q$13 | V13: =$Q$13 | W13: =$Q$13 | X13: =$Q$13 | Y13: =$Q$13 | ... AB13: =$Q$13 | AC13: =SUM(Q13:AB13) | AD13: 1 | AE13: 6000 | AF13: =$AE$13 | AG13: =$AE$13 | AH13: =$AE$13 | AI13: =$AE$13 | AJ13: =$AE$13 | AK13: =$AE$13 | AL13: =$AE$13 | AM13: =$AE$13 | ... AP13: =$AE$13 | AQ13: =SUM(AE13:AP13) | AR13: 2 | AS13: 6000 | AT13: =$AS$13 | AU13: =$AS$13 | AV13: =$AS$13 | AW13: =$AS$13 | AX13: =$AS$13 | AY13: =$AS$13 | AZ13: =$AS$13 | BA13: =$AS$13 | ... BD13: =$AS$13 | BE13: =SUM(AS13:BD13) | BF13: 2 | BG13: 6000 | BH13: =$BG$13 | BI13: =$BG$13 | BJ13: =$BG$13 | BK13: =$BG$13 | BL13: =$BG$13 | BM13: =$BG$13 | BN13: =$BG$13 | BO13: =$BG$13 | ... BR13: =$BG$13 | BS13: =SUM(BG13:BR13) | BT13: 3 | BU13: 6000 | BV13: =$BG$13 | BW13: =$BG$13 | BX13: =$BG$13 | BY13: =$BG$13 | BZ13: =$BG$13 | CA13: =$BG$13 | CB13: =$BG$13 | CC13: =$BG$13 | ... CF13: =$BG$13 | CG13: =SUM(BU13:CF13) | CH13: 3
A14: Project Management & Deployment | C14: 2000 | D14: =$C$14 | E14: =$C$14 | F14: =$C$14 | G14: =$C$14 | H14: =$C$14 | I14: =$C$14 | J14: =$C$14 | K14: =$C$14 | ... N14: =$C$14 | O14: =SUM(C14:N14) | P14: 0.5 | Q14: 2000 | R14: 2000 | S14: 2000 | T14: 2000 | U14: 2000 | V14: 2000 | W14: 2000 | X14: 2000 | Y14: 2000 | Z14: 2000 | AA14: 2000 | AB14: 2000 | AC14: =SUM(Q14:AB14) | AD14: 1 | AE14: 2000 | AF14: 2000 | AG14: 2000 | AH14: 2000 | AI14: 2000 | AJ14: 2000 | AK14: 2000 | AL14: 2000 | AM14: 2000 | AN14: 2000 | AO14: 2000 | AP14: 2000 | AQ14: =SUM(AE14:AP14) | AR14: 1 | AS14: 2000 | AT14: =$AS$14 | AU14: =$AS$14 | AV14: =$AS$14 | AW14: =$AS$14 | AX14: =$AS$14 | AY14: =$AS$14 | AZ14: =$AS$14 | BA14: =$AS$14 | ... BD14: =$AS$14 | BE14: =SUM(AS14:BD14) | BF14: 1 | BG14: 2000 | BH14: 2000 | BI14: 2000 | BJ14: 2000 | BK14: 2000 | BL14: 2000 | BM14: 2000 | BN14: 2000 | BO14: 2000 | BP14: 2000 | BQ14: 2000 | BR14: 2000 | BS14: =SUM(BG14:BR14) | BT14: 1 | BU14: 2000 | BV14: =$BU$14 | BW14: =$BU$14 | BX14: =$BU$14 | BY14: =$BU$14 | BZ14: =$BU$14 | CA14: =$BU$14 | CB14: =$BU$14 | CC14: =$BU$14 | ... CF14: =$BU$14 | CG14: =SUM(BU14:CF14) | CH14: 1
A15: Marketing / Revenue | U15: =$Q$15 | V15: =$Q$15 | W15: =$Q$15 | X15: =$Q$15 | Y15: =$Q$15 | Z15: =$Q$15 | AA15: =$Q$15 | AB15: =$Q$15 | AH15: =$AE$15 | AI15: =$AE$15 | AJ15: =$AE$15 | AK15: =$AE$15 | AL15: =$AE$15 | AM15: =$AE$15 | AN15: =$AE$15 | AO15: =$AE$15 | AP15: =$AE$15 | AT15: =$AS$15 | AU15: =$AS$15 | AV15: =$AS$15 | AW15: =$AS$15 | AX15: =$AS$15 | AY15: =$AS$15 | AZ15: =$AS$15 | BA15: =$AS$15 | ... BD15: =$AS$15 | BI15: =$BG$15 | BJ15: =$BG$15 | BK15: =$BG$15 | BL15: =$BG$15 | BM15: =$BG$15 | BN15: =$BG$15 | BO15: =$BG$15 | BP15: =$BG$15 | ... BR15: =$BG$15 | BW15: =$BG$15 | BX15: =$BG$15 | BY15: =$BG$15 | BZ15: =$BG$15 | CA15: =$BG$15 | CB15: =$BG$15 | CC15: =$BG$15 | CD15: =$BG$15 | ... CF15: =$BG$15
A16: Head of Commercial | C16: 5000 | D16: =$C$16 | E16: =$C$16 | F16: =$C$16 | G16: =$C$16 | H16: =$C$16 | I16: =$C$16 | J16: =$C$16 | K16: =$C$16 | ... N16: =$C$16 | O16: =SUM(C16:N16) | P16: 0.5 | Q16: 4000 | R16: =$Q$16 | S16: =$Q$16 | T16: =$Q$16 | U16: =$Q$16 | V16: =$Q$16 | W16: =$Q$16 | X16: =$Q$16 | Y16: =$Q$16 | ... AB16: =$Q$16 | AC16: =SUM(Q16:AB16) | AD16: 1 | AE16: 4000 | AF16: =$AE$16 | AG16: =$AE$16 | AH16: =$AE$16 | AI16: =$AE$16 | AJ16: =$AE$16 | AK16: =$AE$16 | AL16: =$AE$16 | AM16: =$AE$16 | ... AP16: =$AE$16 | AQ16: =SUM(AE16:AP16) | AR16: 1 | AS16: 4000 | AT16: =$AS$16 | AU16: =$AS$16 | AV16: =$AS$16 | AW16: =$AS$16 | AX16: =$AS$16 | AY16: =$AS$16 | AZ16: =$AS$16 | BA16: =$AS$16 | ... BD16: =$AS$16 | BE16: =SUM(AS16:BD16) | BF16: 1 | BG16: 3000 | BH16: =$BG$16 | BI16: =$BG$16 | BJ16: =$BG$16 | BK16: =$BG$16 | BL16: =$BG$16 | BM16: =$BG$16 | BN16: =$BG$16 | BO16: =$BG$16 | ... BR16: =$BG$16 | BS16: =SUM(BG16:BR16) | BT16: 1 | BU16: 3000 | BV16: =$BG$16 | BW16: =$BG$16 | BX16: =$BG$16 | BY16: =$BG$16 | BZ16: =$BG$16 | CA16: =$BG$16 | CB16: =$BG$16 | CC16: =$BG$16 | ... CF16: =$BG$16 | CG16: =SUM(BU16:CF16) | CH16: 1
A17: Marketing Director | C17: 0 | D17: 0 | E17: 0 | F17: 0 | G17: 0 | H17: 0 | I17: 0 | J17: 0 | K17: 0 | L17: 0 | M17: 0 | N17: 0 | O17: =SUM(C17:N17) | Q17: 2000 | R17: =$Q$17 | S17: =$Q$17 | T17: =$Q$17 | U17: =$Q$17 | V17: =$Q$17 | W17: =$Q$17 | X17: =$Q$17 | Y17: =$Q$17 | ... AB17: =$Q$17 | AC17: =SUM(Q17:AB17) | AD17: 0.5 | AE17: 2000 | AF17: =$AE$17 | AG17: =$AE$17 | AH17: =$AE$17 | AI17: =$AE$17 | AJ17: =$AE$17 | AK17: =$AE$17 | AL17: =$AE$17 | AM17: =$AE$17 | ... AP17: =$AE$17 | AQ17: =SUM(AE17:AP17) | AR17: 1 | AS17: 2000 | AT17: =$AS$17 | AU17: =$AS$17 | AV17: =$AS$17 | AW17: =$AS$17 | AX17: =$AS$17 | AY17: =$AS$17 | AZ17: =$AS$17 | BA17: =$AS$17 | ... BD17: =$AS$17 | BE17: =SUM(AS17:BD17) | BF17: 1 | BG17: 2000 | BH17: =$BG$17 | BI17: =$BG$17 | BJ17: =$BG$17 | BK17: =$BG$17 | BL17: =$BG$17 | BM17: =$BG$17 | BN17: =$BG$17 | BO17: =$BG$17 | ... BR17: =$BG$17 | BS17: =SUM(BG17:BR17) | BT17: 1 | BU17: 2000 | BV17: =$BG$17 | BW17: =$BG$17 | BX17: =$BG$17 | BY17: =$BG$17 | BZ17: =$BG$17 | CA17: =$BG$17 | CB17: =$BG$17 | CC17: =$BG$17 | ... CF17: =$BG$17 | CG17: =SUM(BU17:CF17) | CH17: 1
A18: Sales- Vertical Specialist- Hospitality | C18: 0 | D18: 0 | E18: 0 | F18: 0 | G18: 0 | H18: 0 | I18: 0 | J18: 0 | K18: 0 | L18: 0 | M18: 0 | N18: 0 | O18: =SUM(C18:N18) | Q18: 4000 | R18: =$Q$18 | S18: =$Q$18 | T18: =$Q$18 | U18: =$Q$18 | V18: =$Q$18 | W18: =$Q$18 | X18: =$Q$18 | Y18: =$Q$18 | ... AB18: =$Q$18 | AC18: =SUM(Q18:AB18) | AD18: 0.5 | AE18: 4000 | AF18: =$AE$18 | AG18: =$AE$18 | AH18: =$AE$18 | AI18: =$AE$18 | AJ18: =$AE$18 | AK18: =$AE$18 | AL18: =$AE$18 | AM18: =$AE$18 | ... AP18: =$AE$18 | AQ18: =SUM(AE18:AP18) | AR18: 0.5 | AS18: 4000 | AT18: =$AS$18 | AU18: =$AS$18 | AV18: =$AS$18 | AW18: =$AS$18 | AX18: =$AS$18 | AY18: =$AS$18 | AZ18: =$AS$18 | BA18: =$AS$18 | ... BD18: =$AS$18 | BE18: =SUM(AS18:BD18) | BF18: 1 | BG18: 4000 | BH18: =$BG$18 | BI18: =$BG$18 | BJ18: =$BG$18 | BK18: =$BG$18 | BL18: =$BG$18 | BM18: =$BG$18 | BN18: =$BG$18 | BO18: =$BG$18 | ... BR18: =$BG$18 | BS18: =SUM(BG18:BR18) | BT18: 1 | BU18: 4000 | BV18: =$BG$18 | BW18: =$BG$18 | BX18: =$BG$18 | BY18: =$BG$18 | BZ18: =$BG$18 | CA18: =$BG$18 | CB18: =$BG$18 | CC18: =$BG$18 | ... CF18: =$BG$18 | CG18: =SUM(BU18:CF18) | CH18: 1
A19: Sales- Vertical Specialist- Real Estate | C19: 0 | D19: 0 | E19: 0 | F19: 0 | G19: 0 | H19: 0 | I19: 0 | J19: 0 | K19: 0 | L19: 0 | M19: 0 | N19: 0 | O19: =SUM(C19:N19) | Q19: 0 | R19: =$Q$20 | S19: =$Q$20 | T19: =$Q$20 | U19: =$Q$20 | V19: =$Q$20 | W19: =$Q$20 | X19: =$Q$20 | Y19: =$Q$20 | ... AB19: =$Q$20 | AC19: =SUM(Q19:AB19) | AE19: 4000 | AF19: 4000 | AG19: 4000 | AH19: 4000 | AI19: 4000 | AJ19: 4000 | AK19: 4000 | AL19: 4000 | AM19: 4000 | AN19: 4000 | AO19: 4000 | AP19: 4000 | AQ19: =SUM(AE19:AP19) | AR19: 1 | AS19: 4000 | AT19: =AS19 | AU19: =AT19 | AV19: =AU19 | AW19: =AV19 | AX19: =AW19 | AY19: =AX19 | AZ19: =AY19 | BA19: =AZ19 | ... BD19: =BC19 | BE19: =SUM(AS19:BD19) | BF19: 1 | BG19: 4000 | BH19: =$BG$20 | BI19: =$BG$20 | BJ19: =$BG$20 | BK19: =$BG$20 | BL19: =$BG$20 | BM19: =$BG$20 | BN19: =$BG$20 | BO19: =$BG$20 | ... BR19: =$BG$20 | BS19: =SUM(BG19:BR19) | BT19: 1 | BU19: 4000 | BV19: =$BG$20 | BW19: =$BG$20 | BX19: =$BG$20 | BY19: =$BG$20 | BZ19: =$BG$20 | CA19: =$BG$20 | CB19: =$BG$20 | CC19: =$BG$20 | ... CF19: =$BG$20 | CG19: =SUM(BU19:CF19) | CH19: 1
A20: Sales- Vertical Specialist- Small Firms | C20: 0 | D20: 0 | E20: 0 | F20: 0 | G20: 0 | H20: 0 | I20: 0 | J20: 0 | K20: 0 | L20: 0 | M20: 0 | N20: 0 | O20: 0 | Q20: 0 | R20: =$Q$20 | S20: =$Q$20 | T20: =$Q$20 | U20: =$Q$20 | V20: =$Q$20 | W20: =$Q$20 | X20: =$Q$20 | Y20: =$Q$20 | ... AB20: =$Q$20 | AC20: =SUM(Q20:AB20) | AE20: 0 | AF20: =$AE$20 | AG20: =$AE$20 | AH20: =$AE$20 | AI20: =$AE$20 | AJ20: =$AE$20 | AK20: =$AE$20 | AL20: =$AE$20 | AM20: =$AE$20 | ... AP20: =$AE$20 | AQ20: =SUM(AE20:AP20) | AS20: 0 | AT20: =AS20 | AU20: =AT20 | AV20: =AU20 | AW20: =AV20 | AX20: =AW20 | AY20: =AX20 | AZ20: =AY20 | BA20: =AZ20 | ... BD20: =BC20 | BE20: =SUM(AS20:BD20) | BF20: 0 | BG20: 4000 | BH20: =BG20 | BI20: =BH20 | BJ20: =BI20 | BK20: =BJ20 | BL20: =BK20 | BM20: =BL20 | BN20: =BM20 | BO20: =BN20 | ... BR20: =BQ20 | BS20: =SUM(BG20:BR20) | BT20: 1 | BU20: 4000 | BV20: =$BU$20 | BW20: =$BU$20 | BX20: =$BU$20 | BY20: =$BU$20 | BZ20: =$BU$20 | CA20: =$BU$20 | CB20: =$BU$20 | CC20: =$BU$20 | ... CF20: =$BU$20 | CG20: =SUM(BU20:CF20) | CH20: 1
A21: Sales- Vertical Specialist- Pharma | C21: 0 | D21: 0 | E21: 0 | F21: 0 | G21: 0 | H21: 0 | I21: 0 | J21: 0 | K21: 0 | L21: 0 | M21: 0 | N21: 0 | O21: =SUM(C21:N21) | Q21: 0 | R21: =$Q$22 | S21: =$Q$22 | T21: =$Q$22 | U21: =$Q$22 | V21: =$Q$22 | W21: =$Q$22 | X21: =$Q$22 | Y21: =$Q$22 | ... AB21: =$Q$22 | AC21: =SUM(Q21:AB21) | AE21: 0 | AF21: =$AE$21 | AG21: =$AE$21 | AH21: =$AE$21 | AI21: =$AE$21 | AJ21: =$AE$21 | AK21: =$AE$21 | AL21: =$AE$21 | AM21: =$AE$21 | ... AP21: =$AE$21 | AQ21: =SUM(AE21:AP21) | AS21: 4000 | AT21: =$AS$21 | AU21: =AT21 | AV21: =AU21 | AW21: =AV21 | AX21: =AW21 | AY21: =AX21 | AZ21: =AY21 | BA21: =AZ21 | BB21: =BA21 | ... BD21: =BC21 | BE21: =SUM(AS21:BD21) | BF21: 1 | BG21: 4000 | BH21: =$BG$21 | BI21: =BH21 | BJ21: =BI21 | BK21: =BJ21 | BL21: =BK21 | BM21: =BL21 | BN21: =BM21 | BO21: =BN21 | BP21: =BO21 | ... BR21: =BQ21 | BS21: =SUM(BG21:BR21) | BT21: 1 | BU21: 4000 | BV21: =$BU$21 | BW21: =$BU$21 | BX21: =$BU$21 | BY21: =$BU$21 | BZ21: =$BU$21 | CA21: =$BU$21 | CB21: =$BU$21 | CC21: =$BU$21 | ... CF21: =$BU$21 | CG21: =SUM(BU21:CF21) | CH21: 1
A22: Trainer | C22: 0 | D22: 0 | E22: 0 | F22: 0 | G22: 0 | H22: 0 | I22: 0 | J22: 0 | K22: 0 | L22: 0 | M22: 0 | N22: 0 | O22: =SUM(C22:N22) | Q22: 0 | R22: =$Q$22 | S22: =$Q$22 | T22: =$Q$22 | U22: =$Q$22 | V22: =$Q$22 | W22: =$Q$22 | X22: =$Q$22 | Y22: =$Q$22 | ... AB22: =$Q$22 | AC22: =SUM(Q22:AB22) | AE22: 4000 | AF22: =$AE$22 | AG22: =$AE$22 | AH22: =$AE$22 | AI22: =$AE$22 | AJ22: =$AE$22 | AK22: =$AE$22 | AL22: =$AE$22 | AM22: =$AE$22 | ... AP22: =$AE$22 | AQ22: =SUM(AE22:AP22) | AS22: 4000 | AT22: =$AS$22 | AU22: =$AS$22 | AV22: =$AS$22 | AW22: =$AS$22 | AX22: =$AS$22 | AY22: =$AS$22 | AZ22: =$AS$22 | BA22: =$AS$22 | ... BD22: =$AS$22 | BE22: =SUM(AS22:BD22) | BF22: 1 | BG22: 4000 | BH22: =$BG$22 | BI22: =$BG$22 | BJ22: =$BG$22 | BK22: =$BG$22 | BL22: =$BG$22 | BM22: =$BG$22 | BN22: =$BG$22 | BO22: =$BG$22 | ... BR22: =$BG$22 | BS22: =SUM(BG22:BR22) | BT22: 1 | BU22: 4000 | BV22: =$BG$22 | BW22: =$BG$22 | BX22: =$BG$22 | BY22: =$BG$22 | BZ22: =$BG$22 | CA22: =$BG$22 | CB22: =$BG$22 | CC22: =$BG$22 | ... CF22: =$BG$22 | CG22: =SUM(BU22:CF22) | CH22: 1
A23: Accting / Bookkeeping | C23: 3000 | D23: =$C$23 | E23: =$C$23 | F23: =$C$23 | G23: =$C$23 | H23: =$C$23 | I23: =$C$23 | J23: =$C$23 | K23: =$C$23 | ... N23: =$C$23 | O23: =SUM(C23:N23) | P23: 0.5 | Q23: 2500 | R23: =$Q$23 | S23: =$Q$23 | T23: =$Q$23 | U23: =$Q$23 | V23: =$Q$23 | W23: =$Q$23 | X23: =$Q$23 | Y23: =$Q$23 | ... AB23: =$Q$23 | AC23: =SUM(Q23:AB23) | AD23: 0.5 | AE23: 2500 | AF23: =$AE$23 | AG23: =$AE$23 | AH23: =$AE$23 | AI23: =$AE$23 | AJ23: =$AE$23 | AK23: =$AE$23 | AL23: =$AE$23 | AM23: =$AE$23 | ... AP23: =$AE$23 | AQ23: =SUM(AE23:AP23) | AR23: 0.5 | AS23: 2500 | AT23: =$AS$23 | AU23: =$AS$23 | AV23: =$AS$23 | AW23: =$AS$23 | AX23: =$AS$23 | AY23: =$AS$23 | AZ23: =$AS$23 | BA23: =$AS$23 | ... BD23: =$AS$23 | BE23: =SUM(AS23:BD23) | BF23: 1 | BG23: 2500 | BH23: =$BG$23 | BI23: =$BG$23 | BJ23: =$BG$23 | BK23: =$BG$23 | BL23: =$BG$23 | BM23: =$BG$23 | BN23: =$BG$23 | BO23: =$BG$23 | ... BR23: =$BG$23 | BS23: =SUM(BG23:BR23) | BT23: 1 | BU23: 2500 | BV23: =$BG$23 | BW23: =$BG$23 | BX23: =$BG$23 | BY23: =$BG$23 | BZ23: =$BG$23 | CA23: =$BG$23 | CB23: =$BG$23 | CC23: =$BG$23 | ... CF23: =$BG$23 | CG23: =SUM(BU23:CF23) | CH23: 1
A24: Business Analyst | C24: 0 | D24: =$C$24 | E24: =$C$24 | F24: =$C$24 | G24: =$C$24 | H24: =$C$24 | I24: =$C$24 | J24: =$C$24 | K24: =$C$24 | ... N24: =$C$24 | O24: =SUM(C24:N24) | Q24: 1000 | R24: =$Q$24 | S24: =$Q$24 | T24: =$Q$24 | U24: =$Q$24 | V24: =$Q$24 | W24: =$Q$24 | X24: =$Q$24 | Y24: =$Q$24 | ... AB24: =$Q$24 | AC24: =SUM(Q24:AB24) | AD24: 1 | AE24: 2500 | AF24: =$AE$24 | AG24: =$AE$24 | AH24: =$AE$24 | AI24: =$AE$24 | AJ24: =$AE$24 | AK24: =$AE$24 | AL24: =$AE$24 | AM24: =$AE$24 | ... AP24: =$AE$24 | AQ24: 2500 | AR24: 1 | AS24: 2500 | AT24: =$AS$24 | AU24: =$AS$24 | AV24: =$AS$24 | AW24: =$AS$24 | AX24: =$AS$24 | AY24: =$AS$24 | AZ24: =$AS$24 | BA24: =$AS$24 | ... BD24: =$AS$24 | BE24: 2500 | BF24: 1 | BG24: 2500 | BH24: =$BG$24 | BI24: =$BG$24 | BJ24: =$BG$24 | BK24: =$BG$24 | BL24: =$BG$24 | BM24: =$BG$24 | BN24: =$BG$24 | BO24: =$BG$24 | ... BR24: =$BG$24 | BS24: 2500 | BT24: 1 | BU24: 2500 | BV24: =$BG$24 | BW24: =$BG$24 | BX24: =$BG$24 | BY24: =$BG$24 | BZ24: =$BG$24 | CA24: =$BG$24 | CB24: =$BG$24 | CC24: =$BG$24 | ... CF24: =$BG$24 | CG24: 2500 | CH24: 0.5
A25: Other- Virtual Assistant | C25: 500 | D25: =$C$25 | E25: =$C$25 | F25: =$C$25 | G25: =$C$25 | H25: =$C$25 | I25: =$C$25 | J25: =$C$25 | K25: =$C$25 | ... N25: =$C$25 | O25: =SUM(C25:N25) | P25: 0.5 | Q25: 500 | R25: =$Q$25 | S25: =$Q$25 | T25: =$Q$25 | U25: =$Q$25 | V25: =$Q$25 | W25: =$Q$25 | X25: =$Q$25 | Y25: =$Q$25 | ... AB25: =$Q$25 | AC25: =SUM(Q25:AB25) | AD25: 0.5 | AE25: 500 | AF25: =$AE$25 | AG25: =$AE$25 | AH25: =$AE$25 | AI25: =$AE$25 | AJ25: =$AE$25 | AK25: =$AE$25 | AL25: =$AE$25 | AM25: =$AE$25 | ... AP25: =$AE$25 | AQ25: =SUM(AE25:AP25) | AR25: 0.5 | AS25: 500 | AT25: =$AS$25 | AU25: =$AS$25 | AV25: =$AS$25 | AW25: =$AS$25 | AX25: =$AS$25 | AY25: =$AS$25 | AZ25: =$AS$25 | BA25: =$AS$25 | ... BD25: =$AS$25 | BE25: =SUM(AS25:BD25) | BF25: 0.5 | BG25: 1000 | BH25: =$BG$25 | BI25: =$BG$25 | BJ25: =$BG$25 | BK25: =$BG$25 | BL25: =$BG$25 | BM25: =$BG$25 | BN25: =$BG$25 | BO25: =$BG$25 | ... BR25: =$BG$25 | BS25: =SUM(BG25:BR25) | BT25: 0.5 | BU25: 100 | BV25: =$BG$25 | BW25: =$BG$25 | BX25: =$BG$25 | BY25: =$BG$25 | BZ25: =$BG$25 | CA25: =$BG$25 | CB25: =$BG$25 | CC25: =$BG$25 | ... CF25: =$BG$25 | CG25: =SUM(BU25:CF25) | CH25: 1
C26: =SUM(C8:C25) | D26: =SUM(D8:D24) | E26: =SUM(E8:E24) | F26: =SUM(F8:F24) | G26: =SUM(G8:G24) | H26: =SUM(H8:H24) | I26: =SUM(I8:I24) | J26: =SUM(J8:J24) | K26: =SUM(K8:K24) | ... O26: =SUM(O8:O24) | Q26: =SUM(Q8:Q25) | R26: =SUM(R8:R24) | S26: =SUM(S8:S24) | T26: =SUM(T8:T24) | U26: =SUM(U8:U24) | V26: =SUM(V8:V24) | W26: =SUM(W8:W24) | X26: =SUM(X8:X24) | Y26: =SUM(Y8:Y24) | ... AC26: =SUM(AC8:AC24) | AE26: =SUM(AE8:AE25) | AF26: =SUM(AF8:AF25) | AG26: =SUM(AG8:AG25) | AH26: =SUM(AH8:AH25) | AI26: =SUM(AI8:AI25) | AJ26: =SUM(AJ8:AJ25) | AK26: =SUM(AK8:AK25) | AL26: =SUM(AL8:AL25) | ... AP26: =SUM(AP8:AP25) | AQ26: =SUM(AQ8:AQ24) | AS26: =SUM(AS8:AS25) | AT26: =SUM(AT8:AT24) | AU26: =SUM(AU8:AU24) | AV26: =SUM(AV8:AV24) | AW26: =SUM(AW8:AW24) | AX26: =SUM(AX8:AX24) | AY26: =SUM(AY8:AY24) | AZ26: =SUM(AZ8:AZ24) | BA26: =SUM(BA8:BA24) | ... BE26: =SUM(BE8:BE24) | BG26: =SUM(BG8:BG25) | BH26: =SUM(BH8:BH24) | BI26: =SUM(BI8:BI24) | BJ26: =SUM(BJ8:BJ24) | BK26: =SUM(BK8:BK24) | BL26: =SUM(BL8:BL24) | BM26: =SUM(BM8:BM24) | BN26: =SUM(BN8:BN24) | BO26: =SUM(BO8:BO24) | ... BS26: =SUM(BS8:BS24) | BU26: =SUM(BU8:BU25) | BV26: =SUM(BV8:BV24) | BW26: =SUM(BW8:BW24) | BX26: =SUM(BX8:BX24) | BY26: =SUM(BY8:BY24) | BZ26: =SUM(BZ8:BZ24) | CA26: =SUM(CA8:CA24) | CB26: =SUM(CB8:CB24) | CC26: =SUM(CC8:CC24) | ... CG26: =SUM(CG8:CG24)
A27: FTE | P27: =SUM(P8:P26) | AD27: =SUM(AD8:AD26) | AR27: =SUM(AR8:AR26) | BF27: =SUM(BF8:BF25) | BT27: =SUM(BT8:BT25) | CH27: =SUM(CH8:CH25)
AO315: 1
AO316: 1
AO317: 1
AO318: 1
AO319: 1
AO320: 1
AO321: 1
AO322: 1
AO323: 1
AO324: 1
I406: 12
I407: =O25/I406
H408: 70000
H409: 12
H410: =H408/H409

Sheet Departmental Expenses
D2: 2025 | R2: 2026 | AF2: 2027 | AT2: 2028
D3: 45658 | E3: 45689 | F3: 45717 | G3: 45748 | H3: 45778 | I3: 45809 | J3: 45839 | K3: 45870 | L3: 45901 | M3: 45931 | N3: 45962 | O3: 45992 | P3: Total | R3: 46023 | S3: 46083 | T3: 46082 | U3: 46113 | V3: 46143 | W3: 46174 | X3: 46204 | Y3: 46235 | Z3: 13394 | AA3: 46296 | AB3: 46327 | AC3: 46357 | AD3: Total | AF3: 46388 | AG3: 46419 | AH3: 46447 | AI3: 46478 | AJ3: 46508 | AK3: 46539 | AL3: 46569 | AM3: 46600 | AN3: 46631 | AO3: 46661 | AP3: 46692 | AQ3: 46722 | AR3: Total | AT3: 46753 | AU3: 2/1/202 | AV3: 46813 | AW3: 46844 | AX3: 46874 | AY3: 46905 | AZ3: 46935 | BA3: 46966 | BB3: 46997 | BC3: 47027 | BD3: 47058 | BE3: 46722 | BF3: Total
A5: Sales and Marketing
