Workbook

Sheet KB Co Assumptions
B1: Kate Burda & Co | 2027 Advisory Proforma | C1: Assumptions | D1: Notes
B3: REVENUE (Monthly Gross — Recurring Clients)
B4: Flying Horse | C4: 12500 | D4: Open-ended
B5: CHM Warnick / MPEA | C5: 4800 | D5: Active retainer
B6: Wylie (gross) | C6: 6000
B7: FEI / Miguel Molina | C7: 5500 | D7: Net to house after Tristan split
B8: DragonSteel | C8: 4000 | D8: Continuing from Oct 2026
B9: TOTAL MONTHLY RECURRING REVENUE | C9: =SUM(C4:C8)
B11: NEW CLIENTS — ONE-TIME ENGAGEMENT FEES (Advisory + candidate Ignite beta partners)
B12: Client | C12: One-Time Fee | D12: Notes | E12: Target Month (EDIT THIS)
B13: New Client 1 (placeholder — May) | C13: 25000 | D13: One-time engagement fee. Placeholder timing from Session 1 growth thesis — move once a real deal closes. | E13: May
B14: New Client 2 (placeholder — Aug) | C14: 25000 | D14: One-time engagement fee. Placeholder timing from Session 1 growth thesis — move once a real deal closes. | E14: Aug
B15: New Client 3 (placeholder — Nov) | C15: 25000 | D15: One-time engagement fee. Placeholder timing from Session 1 growth thesis — move once a real deal closes. | E15: Nov
B16: TOTAL ONE-TIME NEW-CLIENT FEES (annual) | C16: =SUM(C13:C15)
B17: TOTAL 2027 REVENUE (Recurring × 12 + One-Time Fees) | C17: =C9*12+C16
B19: FIXED MONTHLY EXPENSES
B20: Kate Salary | C20: 7000 | D20: Monthly draw
B21: Tristan (contractor) | C21: 1500 | D21: Tied to FEI
B22: SBA Loan | C22: 674 | D22: Continuing
B23: American Airlines | C23: 2500 | D23: Travel budget
B24: ZoomInfo | C24: 833 | D24: Intent signals
B25: AT&T | C25: 198 | D25: Phone
B26: Adobe | C26: 97.4 | D26: Creative suite
B27: Ellavator.ai | C27: 250 | D27: AI branding
B28: Taplio | C28: 65 | D28: LinkedIn content
B29: Vercel | C29: 85 | D29: Ignite hosting
B30: Supabase | C30: 25 | D30: Ignite database
B31: Anthropic/Claude | C31: 49 | D31: AI tool
... B38: Annual Subs (amortized) | C38: 490.25 | D38: SearchAtlas, Calendly, Canva, Zoom, ISHC, Clear
B39: TOTAL MONTHLY OPEX | C39: =SUM(C20:C38)
B40: Tax Rate | C40: 0.15 | D40: Applied to pre-tax profit (was stored as text ‘15%’ in source — now a real number so formulas can reference it)
B42: DEBT ENTERING 2027
B43: IRS | C43: $24,835 | D43: Target: pay off Q1 2027
B44: SBA Loan | C44: $674/mo continuing | D44: Long term
B45: Mercedes (Ally) | C45: $1,125/mo continuing | D45: Personal
B46: Scottsdale HELOC | C46: $500/mo continuing | D46: Keep current pace
B47: Affirm X-Chair (0%) | C47: $75.42/mo through Jul 2027
B48: Affirm Peloton (0%) | C48: $74.05/mo through Jan 2028
B50: KEY TARGETS
B51: IRS paid off | C51: March 2027
...

Sheet Jan-Dec Cash Flow
A1: Kate Burda & Co | Advisory P&L | 2027
B3: Jan | C3: Feb | D3: Mar | E3: Apr | F3: May | G3: Jun | H3: Jul | I3: Aug | J3: Sep | K3: Oct | L3: Nov | M3: Dec | N3: Annual
A5: GROSS REVENUE — RECURRING CLIENTS
A6: ='KB Co Assumptions'!B4 | B6: ='KB Co Assumptions'!C4 | C6: =B6 | D6: =C6 | E6: =D6 | F6: =E6 | G6: =F6 | H6: =G6 | I6: =H6 | J6: =I6 | ... M6: =L6 | N6: =SUM(B6:M6) | P6: Minimum
A7: ='KB Co Assumptions'!B5 | B7: ='KB Co Assumptions'!C5 | C7: =B7 | D7: =C7 | E7: =D7 | F7: =E7 | G7: =F7 | H7: =G7 | I7: =H7 | J7: =I7 | ... M7: =L7 | N7: =SUM(B7:M7) | P7: Goal | Q7: 350000 | S7: Adj Goal | T7: =(Q7/12)*Q8 | V7: Current Gross Diff | W7: =N17-T7
A8: ='KB Co Assumptions'!B6 | B8: ='KB Co Assumptions'!C6 | C8: =B8 | D8: =C8 | E8: =D8 | F8: =E8 | G8: =F8 | H8: =G8 | I8: =H8 | J8: =I8 | ... M8: =L8 | N8: =SUM(B8:M8) | P8: Months | Q8: ='Kate Co Breakdown'!I5 | S8: Taxes | T8: =T7*'KB Co Assumptions'!$C$40
A9: ='KB Co Assumptions'!B7 | B9: ='KB Co Assumptions'!C7 | C9: =B9 | D9: =C9 | E9: =D9 | F9: =E9 | G9: =F9 | H9: =G9 | I9: =H9 | J9: =I9 | ... M9: =L9 | N9: =SUM(B9:M9) | S9: Net | T9: =T7-T8
A10: ='KB Co Assumptions'!B8 | B10: ='KB Co Assumptions'!C8 | C10: =B10 | D10: =C10 | E10: =D10 | F10: =E10 | G10: =F10 | H10: =G10 | I10: =H10 | J10: =I10 | ... M10: =L10 | N10: =SUM(B10:M10)
P11: Aspirational
A12: ONE-TIME ENGAGEMENT FEES — NEW ADVISORY / IGNITE-BETA CLIENTS (edit the Target Month in KB Co Assumptions to move a fee) | P12: Goal | Q12: 500000 | S12: Adj Goal | T12: =(Q12/12)*Q13 | V12: Aspirational Gross Diff | W12: =N17-T12
A13: ='KB Co Assumptions'!B13 | B13: =IF(B$3='KB Co Assumptions'!$E$13,'KB Co Assumptions'!$C$13,0) | C13: =IF(C$3='KB Co Assumptions'!$E$13,'KB Co Assumptions'!$C$13,0) | D13: =IF(D$3='KB Co Assumptions'!$E$13,'KB Co Assumptions'!$C$13,0) | E13: =IF(E$3='KB Co Assumptions'!$E$13,'KB Co Assumptions'!$C$13,0) | F13: =IF(F$3='KB Co Assumptions'!$E$13,'KB Co Assumptions'!$C$13,0) | G13: =IF(G$3='KB Co Assumptions'!$E$13,'KB Co Assumptions'!$C$13,0) | H13: =IF(H$3='KB Co Assumptions'!$E$13,'KB Co Assumptions'!$C$13,0) | I13: =IF(I$3='KB Co Assumptions'!$E$13,'KB Co Assumptions'!$C$13,0) | ... M13: =IF(M$3='KB Co Assumptions'!$E$13,'KB Co Assumptions'!$C$13,0) | N13: =SUM(B13:M13) | P13: Months | Q13: 12 | S13: Taxes | T13: =T12*'KB Co Assumptions'!$C$40
A14: ='KB Co Assumptions'!B14 | B14: =IF(B$3='KB Co Assumptions'!$E$14,'KB Co Assumptions'!$C$14,0) | C14: =IF(C$3='KB Co Assumptions'!$E$14,'KB Co Assumptions'!$C$14,0) | D14: =IF(D$3='KB Co Assumptions'!$E$14,'KB Co Assumptions'!$C$14,0) | E14: =IF(E$3='KB Co Assumptions'!$E$14,'KB Co Assumptions'!$C$14,0) | F14: =IF(F$3='KB Co Assumptions'!$E$14,'KB Co Assumptions'!$C$14,0) | G14: =IF(G$3='KB Co Assumptions'!$E$14,'KB Co Assumptions'!$C$14,0) | H14: =IF(H$3='KB Co Assumptions'!$E$14,'KB Co Assumptions'!$C$14,0) | I14: =IF(I$3='KB Co Assumptions'!$E$14,'KB Co Assumptions'!$C$14,0) | ... M14: =IF(M$3='KB Co Assumptions'!$E$14,'KB Co Assumptions'!$C$14,0) | N14: =SUM(B14:M14) | S14: Net | T14: =T12-T13
A15: ='KB Co Assumptions'!B15 | B15: =IF(B$3='KB Co Assumptions'!$E$15,'KB Co Assumptions'!$C$15,0) | C15: =IF(C$3='KB Co Assumptions'!$E$15,'KB Co Assumptions'!$C$15,0) | D15: =IF(D$3='KB Co Assumptions'!$E$15,'KB Co Assumptions'!$C$15,0) | E15: =IF(E$3='KB Co Assumptions'!$E$15,'KB Co Assumptions'!$C$15,0) | F15: =IF(F$3='KB Co Assumptions'!$E$15,'KB Co Assumptions'!$C$15,0) | G15: =IF(G$3='KB Co Assumptions'!$E$15,'KB Co Assumptions'!$C$15,0) | H15: =IF(H$3='KB Co Assumptions'!$E$15,'KB Co Assumptions'!$C$15,0) | I15: =IF(I$3='KB Co Assumptions'!$E$15,'KB Co Assumptions'!$C$15,0) | ... M15: =IF(M$3='KB Co Assumptions'!$E$15,'KB Co Assumptions'!$C$15,0) | N15: =SUM(B15:M15)
A17: TOTAL GROSS REVENUE | B17: =SUM(B6:B10)+SUM(B13:B15) | C17: =SUM(C6:C10)+SUM(C13:C15) | D17: =SUM(D6:D10)+SUM(D13:D15) | E17: =SUM(E6:E10)+SUM(E13:E15) | F17: =SUM(F6:F10)+SUM(F13:F15) | G17: =SUM(G6:G10)+SUM(G13:G15) | H17: =SUM(H6:H10)+SUM(H13:H15) | I17: =SUM(I6:I10)+SUM(I13:I15) | ... M17: =SUM(M6:M10)+SUM(M13:M15) | N17: =SUM(B17:M17)
A19: OPERATING EXPENSES
A20: ='KB Co Assumptions'!B20 | B20: ='KB Co Assumptions'!C20 | C20: =B20 | D20: =C20 | E20: =D20 | F20: =E20 | G20: =F20 | H20: =G20 | I20: =H20 | J20: =I20 | ... M20: =L20 | N20: =SUM(B20:M20)
A21: ='KB Co Assumptions'!B21 | B21: ='KB Co Assumptions'!C21 | C21: =B21 | D21: =C21 | E21: =D21 | F21: =E21 | G21: =F21 | H21: =G21 | I21: =H21 | J21: =I21 | ... M21: =L21 | N21: =SUM(B21:M21)
A22: ='KB Co Assumptions'!B22 | B22: ='KB Co Assumptions'!C22 | C22: =B22 | D22: =C22 | E22: =D22 | F22: =E22 | G22: =F22 | H22: =G22 | I22: =H22 | J22: =I22 | ... M22: =L22 | N22: =SUM(B22:M22)
A23: ='KB Co Assumptions'!B23 | B23: ='KB Co Assumptions'!C23 | C23: =B23 | D23: =C23 | E23: =D23 | F23: =E23 | G23: =F23 | H23: =G23 | I23: =H23 | J23: =I23 | ... M23: =L23 | N23: =SUM(B23:M23)
A24: ='KB Co Assumptions'!B24 | B24: ='KB Co Assumptions'!C24 | C24: =B24 | D24: =C24 | E24: =D24 | F24: =E24 | G24: =F24 | H24: =G24 | I24: =H24 | J24: =I24 | ... M24: =L24 | N24: =SUM(B24:M24)
A25: ='KB Co Assumptions'!B25 | B25: ='KB Co Assumptions'!C25 | C25: =B25 | D25: =C25 | E25: =D25 | F25: =E25 | G25: =F25 | H25: =G25 | I25: =H25 | J25: =I25 | ... M25: =L25 | N25: =SUM(B25:M25)
A26: ='KB Co Assumptions'!B26 | B26: ='KB Co Assumptions'!C26 | C26: =B26 | D26: =C26 | E26: =D26 | F26: =E26 | G26: =F26 | H26: =G26 | I26: =H26 | J26: =I26 | ... M26: =L26 | N26: =SUM(B26:M26)
A27: ='KB Co Assumptions'!B27 | B27: ='KB Co Assumptions'!C27 | C27: =B27 | D27: =C27 | E27: =D27 | F27: =E27 | G27: =F27 | H27: =G27 | I27: =H27 | J27: =I27 | ... M27: =L27 | N27: =SUM(B27:M27)
A28: ='KB Co Assumptions'!B28 | B28: ='KB Co Assumptions'!C28 | C28: =B28 | D28: =C28 | E28: =D28 | F28: =E28 | G28: =F28 | H28: =G28 | I28: =H28 | J28: =I28 | ... M28: =L28 | N28: =SUM(B28:M28)
A29: ='KB Co Assumptions'!B29 | B29: ='KB Co Assumptions'!C29 | C29: =B29 | D29: =C29 | E29: =D29 | F29: =E29 | G29: =F29 | H29: =G29 | I29: =H29 | J29: =I29 | ... M29: =L29 | N29: =SUM(B29:M29)
A30: ='KB Co Assumptions'!B30 | B30: ='KB Co Assumptions'!C30 | C30: =B30 | D30: =C30 | E30: =D30 | F30: =E30 | G30: =F30 | H30: =G30 | I30: =H30 | J30: =I30 | ... M30: =L30 | N30: =SUM(B30:M30)
A31: ='KB Co Assumptions'!B31 | B31: ='KB Co Assumptions'!C31 | C31: =B31 | D31: =C31 | E31: =D31 | F31: =E31 | G31: =F31 | H31: =G31 | I31: =H31 | J31: =I31 | ... M31: =L31 | N31: =SUM(B31:M31)
... A38: ='KB Co Assumptions'!B38 | B38: ='KB Co Assumptions'!C38 | C38: =B38 | D38: =C38 | E38: =D38 | F38: =E38 | G38: =F38 | H38: =G38 | I38: =H38 | J38: =I38 | ... M38: =L38 | N38: =SUM(B38:M38)
A39: TOTAL OPERATING EXPENSES | B39: =SUM(B20:B38) | C39: =SUM(C20:C38) | D39: =SUM(D20:D38) | E39: =SUM(E20:E38) | F39: =SUM(F20:F38) | G39: =SUM(G20:G38) | H39: =SUM(H20:H38) | I39: =SUM(I20:I38) | ... N39: =SUM(N20:N38)
A41: PRE-TAX PROFIT | B41: =B17-B39 | C41: =C17-C39 | D41: =D17-D39 | E41: =E17-E39 | F41: =F17-F39 | G41: =G17-G39 | H41: =H17-H39 | I41: =I17-I39 | ... M41: =M17-M39 | N41: =SUM(B41:M41)
A42: Tax (15%) | B42: =B41*'KB Co Assumptions'!$C$40 | C42: =C41*'KB Co Assumptions'!$C$40 | D42: =D41*'KB Co Assumptions'!$C$40 | E42: =E41*'KB Co Assumptions'!$C$40 | F42: =F41*'KB Co Assumptions'!$C$40 | G42: =G41*'KB Co Assumptions'!$C$40 | H42: =H41*'KB Co Assumptions'!$C$40 | I42: =I41*'KB Co Assumptions'!$C$40 | ... M42: =M41*'KB Co Assumptions'!$C$40 | N42: =SUM(B42:M42)
A43: NET PROFIT (after tax) | B43: =B41-B42 | C43: =C41-C42 | D43: =D41-D42 | E43: =E41-E42 | F43: =F41-F42 | G43: =G41-G42 | H43: =H41-H42 | I43: =I41-I42 | ... M43: =M41-M42 | N43: =SUM(B43:M43)
A45: IRS Payoff (Q1 aggressive) | B45: 8278.33 | C45: 8278.33 | D45: 8278.34 | E45: 0 | F45: 0 | G45: 0 | H45: 0 | I45: 0 | J45: 0 | K45: 0 | L45: 0 | M45: 0 | N45: =SUM(B45:M45)
A47: CUMULATIVE FREE CASH | B47: =B43-B45 | C47: =C43-C45 | D47: =D43-D45 | E47: =E43-E45 | F47: =F43-F45 | G47: =G43-G45 | H47: =H43-H45 | I47: =I43-I45 | ... M47: =M43-M45 | N47: =SUM(B47:M47)
A49: ANNUAL SUMMARY
A50: Total Revenue | B50: =N17
A51: Total Operating Expenses | B51: =N39
A52: Net Profit (after tax) | B52: =N43
A53: IRS Payoff | B53: =N45
A54: Total Free Cash | B54: =N47
...

Sheet Kate Co Breakdown
G4: Current
C5: Monthly Expenses | H5: Months | I5: 12
H6: Revenue | I6: Expenses | K6: Profit | M6: =H7 | N6: Business Income
C7: SupaBase | D7: 25 | G7: Annual | H7: ='Jan-Dec Cash Flow'!N13 | I7: =D51*I5 | K7: =H7-I7 | M7: 0.15 | N7: Taxes
G8: Monthly | H8: =H7/I5 | I8: =D51 | K8: =H8-I8
C9: Adobe | D9: =I32 | M9: =M6-(M6*M7) | N9: NOI
C11: LinkedIn- Sales Navigator | D11: 107
C13: ZoomInfo | D13: 883
C15: Quickbooks | D15: 80
C17: ActiveCampaign | D17: 199 | M17: 3274
C19: Slack | D19: 62
C21: AT&T | D21: 198
D23: 0
C25: Ella | D25: 250
C27: MeetGeek | D27: 19
C29: Annual Subscriptions | D29: ='Annual Subscriptions'!C21/12 | H29: Go Daddy | I29: Adobe
H30: 9.58 | I30: 64.94
C31: Taplio | D31: 65 | H31: 64 | I31: 32.46
H32: 11.72 | I32: =SUM(I30:I31)
C33: OpenAi | D33: 22 | H33: 17.03
H34: =SUM(H30:H33)
C35: Dripify | D35: 85
C37: Go Daddy | D37: =H34
C39: Trello | D39: 65 | J39: 3264
C41: AWS | D41: 0
C43: AA | D43: 2000
C45: SBA | D45: 674
C47: Employee_ Kate Burda | D47: =Breakdown!J7
C49: Tax Burden | D49: 0
D51: =SUM(D7:D50)
C53: Wylie | D53: 3000
C54: CHM | D54: 4800
C55: Wylie | D55: 1000
C56: FEI | D56: 2000
C57: Flying Horse | D57: 2000
D58: =SUM(D53:D57)-D51

Sheet Annual Subscriptions
B7: Annual Subscription
B8: Zoho
B9: Search Atlas
B11: Canva | C11: 120
B12: Hightail | C12: 180
B13: Zoom | C13: 160
B14: Masterclass | C14: 180
B15: Headspace | C15: 72
B16: HBR | C16: 0
B17: Yoast | C17: 0
B18: Elementor | C18: 0
B19: ISHC | C19: 1000
B20: Clear | C20: 189
C21: =SUM(C8:C20) | E21: =C21/12

Sheet Personal Budget Assumptions
A1: Kate Burda | Personal Budget | Monthly View
A2: Category | B2: Monthly ($) | C2: Annual ($) | D2: Notes
A4: INCOME
A5: Kate Salary (gross) | B5: 7000 | C5: =B5*'Kate Co Breakdown'!I5 | D5: Before 15% tax
A6: Less: Tax (15%) | B6: 0 | C6: =B6*'Kate Co Breakdown'!$I$5
A7: Chicago Net (income) | B7: =Chicago!F11 | C7: =B7*'Kate Co Breakdown'!$I$5 | D7: Rent $2,400 less mortgage/assoc/cable
A8: TOTAL MONTHLY INCOME (take-home) | B8: =B5+B6+B7 | C8: =B8*'Kate Co Breakdown'!$I$5
A10: FIXED MONTHLY EXPENSES
A11: Health Insurance (starts July 2026) | B11: =Breakdown!D6 | C11: =B11*'Kate Co Breakdown'!$I$5
A12: Mercedes (Ally) | B12: =Breakdown!D12 | C12: =B12*'Kate Co Breakdown'!$I$5 | D12: Car note
A13: State Farm Insurance | B13: ='Monthly Spending'!H33 | C13: =B13*'Kate Co Breakdown'!$I$5 | D13: Audi, Mercedes, Dallas home, personal
A14: Home Security (Alert 360) | B14: =Breakdown!D16 | C14: =B14*'Kate Co Breakdown'!$I$5
A15: Northwestern Mutual | B15: =Breakdown!D18 | C15: =B15*'Kate Co Breakdown'!$I$5
A16: Scottsdale Net (deficit) | B16: =-(Scottsdale!F12) | C16: =B16*'Kate Co Breakdown'!$I$5 | D16: Rent $3,500 less mortgage/HELOC/assoc
A17: TOTAL FIXED EXPENSES | B17: =B11+B12+B13+B14+B15+B16 | C17: =B17*'Kate Co Breakdown'!$I$5
A19: MONTHLY VARIABLE SPENDING
A20: Groceries | B20: ='Monthly Spending'!D9 | C20: =B20*'Kate Co Breakdown'!$I$5
A21: Gas | B21: ='Monthly Spending'!D7 | C21: =B21*'Kate Co Breakdown'!$I$5
A22: Dry Cleaning and Tailor | B22: 100 | C22: =B22*'Kate Co Breakdown'!$I$5
A23: Apple | B23: 277 | C23: =B23*'Kate Co Breakdown'!$I$5
A24: Orangetheory Fitness | B24: 110.09 | C24: =B24*'Kate Co Breakdown'!$I$5 | D24: Recurring, varies $109-110.09
A25: Credit Pulse | B25: 19.99 | C25: =B25*'Kate Co Breakdown'!$I$5
A26: Affirm XChair | B26: 76 | C26: =B26*'Kate Co Breakdown'!$I$5
A27: Affirm Peloton | B27: 74 | C27: =B27*'Kate Co Breakdown'!$I$5
A28: Zips Car Wash | B28: 22 | C28: =B28*'Kate Co Breakdown'!$I$5 | D28: Separate from existing Car Wash line; varies $17.99-26.84
A29: Pool (maintenance supplies) | B29: ='Monthly Spending'!D15 | C29: =B29*'Kate Co Breakdown'!$I$5
A30: Pierce (Dog) | B30: ='Monthly Spending'!D12 | C30: =B30*'Kate Co Breakdown'!$I$5
A31: Nails | B31: ='Monthly Spending'!D13 | C31: =B31*'Kate Co Breakdown'!$I$5 | D31: Averaged $120 per 3 weeks
A32: Personal Grooming | B32: ='Monthly Spending'!D14 | C32: =B32*'Kate Co Breakdown'!$I$5 | D32: Amortized: Dr. Perez x4, haircut x7, face
A33: Doc / Medical | B33: ='Monthly Spending'!D8 | C33: =B33*'Kate Co Breakdown'!$I$5
A34: Ro Health (weight loss) | B34: 297 | C34: =B34*'Kate Co Breakdown'!$I$5 | D34: Active
B35: 0 | C35: =B35*'Kate Co Breakdown'!$I$5
A36: TOTAL VARIABLE SPENDING | B36: 2944.75 | C36: =B36*'Kate Co Breakdown'!$I$5
A38: PERSONAL SUBSCRIPTIONS (monthly)
A39: Apple (total) | B39: ='Monthly Spending'!H16 | C39: =B39*'Kate Co Breakdown'!$I$5 | D39: TV $12.99, Storage $4.32, Other $2.99, Prime $9.73
A40: Audible | B40: ='Monthly Spending'!H17 | C40: =B40*'Kate Co Breakdown'!$I$5
A41: Peacock | B41: ='Monthly Spending'!H19 | C41: =B41*'Kate Co Breakdown'!$I$5
A42: Fubo | B42: ='Monthly Spending'!H20 | C42: =B42*'Kate Co Breakdown'!$I$5
A43: Paramount | B43: ='Monthly Spending'!H21 | C43: =B43*'Kate Co Breakdown'!$I$5
A44: Lifetime (gym) | B44: ='Monthly Spending'!H22 | C44: =B44*'Kate Co Breakdown'!$I$5
...

Sheet Personal Jan-Dec
A2: Kate Burda | Personal Cash Flow | 2027
B4: Jan | C4: Feb | D4: Mar | E4: Apr | F4: May | G4: Jun | H4: Jul | I4: Aug | J4: Sep | K4: Oct | L4: Nov | M4: Dec | N4: Annual
A6: PERSONAL INCOME
A7: ='Personal Budget Assumptions'!A5 | B7: 7000 | C7: =B7 | D7: =C7 | E7: =D7 | F7: =E7 | G7: =F7 | H7: =G7 | I7: =H7 | J7: =I7 | ... M7: =L7 | N7: =SUM(B7:M7)
A8: ='Personal Budget Assumptions'!A7 | B8: ='Personal Budget Assumptions'!B7 | C8: =B8 | D8: =C8 | E8: =D8 | F8: =E8 | G8: =F8 | H8: =G8 | I8: =H8 | J8: =I8 | ... M8: =L8 | N8: =SUM(B8:M8)
A9: TOTAL INCOME | B9: =SUM(B7:B8) | C9: =B9 | D9: =C9 | E9: =D9 | F9: =E9 | G9: =F9 | H9: =G9 | I9: =H9 | J9: =I9 | ... M9: =L9 | N9: =SUM(B9:M9)
A11: FIXED EXPENSES
A12: ='Personal Budget Assumptions'!A11 | B12: ='Personal Budget Assumptions'!B11 | C12: =B12 | D12: =C12 | E12: =D12 | F12: =E12 | G12: =F12 | H12: =G12 | I12: =H12 | J12: =I12 | ... M12: =L12 | N12: =SUM(B12:M12)
A13: ='Personal Budget Assumptions'!A12 | B13: ='Personal Budget Assumptions'!B12 | C13: =B13 | D13: =C13 | E13: =D13 | F13: =E13 | G13: =F13 | H13: =G13 | I13: =H13 | J13: =I13 | ... M13: =L13 | N13: =SUM(B13:M13)
A14: ='Personal Budget Assumptions'!A13 | B14: ='Personal Budget Assumptions'!B13 | C14: =B14 | D14: =C14 | E14: =D14 | F14: =E14 | G14: =F14 | H14: =G14 | I14: =H14 | J14: =I14 | ... M14: =L14 | N14: =SUM(B14:M14)
A15: ='Personal Budget Assumptions'!A14 | B15: ='Personal Budget Assumptions'!B14 | C15: =B15 | D15: =C15 | E15: =D15 | F15: =E15 | G15: =F15 | H15: =G15 | I15: =H15 | J15: =I15 | ... M15: =L15 | N15: =SUM(B15:M15)
A16: ='Personal Budget Assumptions'!A15 | B16: ='Personal Budget Assumptions'!B15 | C16: =B16 | D16: =C16 | E16: =D16 | F16: =E16 | G16: =F16 | H16: =G16 | I16: =H16 | J16: =I16 | ... M16: =L16 | N16: =SUM(B16:M16)
A17: ='Personal Budget Assumptions'!A16 | B17: ='Personal Budget Assumptions'!B16 | C17: =B17 | D17: =C17 | E17: =D17 | F17: =E17 | G17: =F17 | H17: =G17 | I17: =H17 | J17: =I17 | ... M17: =L17 | N17: =SUM(B17:M17)
A18: TOTAL FIXED | B18: =SUM(B12:B17) | C18: =B18 | D18: =C18 | E18: =D18 | F18: =E18 | G18: =F18 | H18: =G18 | I18: =H18 | J18: =I18 | ... M18: =L18 | N18: =SUM(N12:N17)
A20: VARIABLE SPENDING
A21: ='Personal Budget Assumptions'!A20 | B21: ='Personal Budget Assumptions'!B20 | C21: =B21 | D21: =C21 | E21: =D21 | F21: =E21 | G21: =F21 | H21: =G21 | I21: =H21 | J21: =I21 | ... M21: =L21 | N21: =SUM(B21:M21)
A22: ='Personal Budget Assumptions'!A21 | B22: ='Personal Budget Assumptions'!B21 | C22: =B22 | D22: =C22 | E22: =D22 | F22: =E22 | G22: =F22 | H22: =G22 | I22: =H22 | J22: =I22 | ... M22: =L22 | N22: =SUM(B22:M22)
A23: ='Personal Budget Assumptions'!A22 | B23: ='Personal Budget Assumptions'!B22 | C23: =B23 | D23: =C23 | E23: =D23 | F23: =E23 | G23: =F23 | H23: =G23 | I23: =H23 | J23: =I23 | ... M23: =L23 | N23: =SUM(B23:M23)
A24: ='Personal Budget Assumptions'!A23 | B24: ='Personal Budget Assumptions'!B23 | C24: =B24 | D24: =C24 | E24: =D24 | F24: =E24 | G24: =F24 | H24: =G24 | I24: =H24 | J24: =I24 | ... M24: =L24 | N24: =SUM(B24:M24)
A25: ='Personal Budget Assumptions'!A24 | B25: ='Personal Budget Assumptions'!B24 | C25: =B25 | D25: =C25 | E25: =D25 | F25: =E25 | G25: =F25 | H25: =G25 | I25: =H25 | J25: =I25 | ... M25: =L25 | N25: =SUM(B25:M25)
A26: ='Personal Budget Assumptions'!A25 | B26: ='Personal Budget Assumptions'!B25 | C26: =B26 | D26: =C26 | E26: =D26 | F26: =E26 | G26: =F26 | H26: =G26 | I26: =H26 | J26: =I26 | ... M26: =L26 | N26: =SUM(B26:M26)
A27: ='Personal Budget Assumptions'!A26 | B27: ='Personal Budget Assumptions'!B26 | C27: =B27 | D27: =C27 | E27: =D27 | F27: =E27 | G27: =F27 | H27: =G27 | J27: =I27 | K27: =J27 | L27: =K27 | M27: =L27 | N27: =SUM(B27:M27)
A28: ='Personal Budget Assumptions'!A27 | B28: ='Personal Budget Assumptions'!B27 | C28: =B28 | D28: =C28 | E28: =D28 | F28: =E28 | G28: =F28 | H28: =G28 | I28: =H28 | J28: =I28 | ... M28: =L28 | N28: =SUM(B28:M28)
A29: ='Personal Budget Assumptions'!A28 | B29: ='Personal Budget Assumptions'!B28 | C29: =B29 | D29: =C29 | E29: =D29 | F29: =E29 | G29: =F29 | H29: =G29 | I29: =H29 | J29: =I29 | ... M29: =L29 | N29: =SUM(B29:M29)
A30: ='Personal Budget Assumptions'!A29 | B30: ='Personal Budget Assumptions'!B29 | C30: =B30 | D30: =C30 | E30: =D30 | F30: =E30 | G30: =F30 | H30: =G30 | I30: =H30 | J30: =I30 | ... M30: =L30 | N30: =SUM(B30:M30)
A31: ='Personal Budget Assumptions'!A30 | B31: ='Personal Budget Assumptions'!B30 | C31: =B31 | D31: =C31 | E31: =D31 | F31: =E31 | G31: =F31 | H31: =G31 | I31: =H31 | J31: =I31 | ... M31: =L31 | N31: =SUM(B31:M31)
A32: ='Personal Budget Assumptions'!A31 | B32: ='Personal Budget Assumptions'!B31 | C32: =B32 | D32: =C32 | E32: =D32 | F32: =E32 | G32: =F32 | H32: =G32 | I32: =H32 | J32: =I32 | ... M32: =L32 | N32: =SUM(B32:M32)
A33: ='Personal Budget Assumptions'!A32 | B33: ='Personal Budget Assumptions'!B32 | C33: =B33 | D33: =C33 | E33: =D33 | F33: =E33 | G33: =F33 | H33: =G33 | I33: =H33 | J33: =I33 | ... M33: =L33 | N33: =SUM(C33:M33)
A34: ='Personal Budget Assumptions'!A33 | B34: ='Personal Budget Assumptions'!B33 | C34: =B34 | D34: =C34 | E34: =D34 | F34: =E34 | G34: =F34 | H34: =G34 | I34: =H34 | J34: =I34 | ... M34: =L34 | N34: =SUM(B34:M34)
A35: ='Personal Budget Assumptions'!A34 | B35: ='Personal Budget Assumptions'!B34 | C35: =B35 | D35: =C35 | E35: =D35 | F35: =E35 | G35: =F35 | H35: =G35 | I35: =H35 | J35: =I35 | ... M35: =L35 | N35: =SUM(B35:M35)
A36: TOTAL VARIABLE | B36: =SUM(B21:B35) | C36: =SUM(C21:C35) | D36: =SUM(D21:D35) | E36: =SUM(E21:E35) | F36: =SUM(F21:F35) | G36: =SUM(G21:G35) | H36: =SUM(H21:H35) | I36: =SUM(I21:I35) | ... N36: =SUM(N21:N35)
A38: SUBSCRIPTIONS
A39: ='Personal Budget Assumptions'!A39 | B39: ='Personal Budget Assumptions'!B39 | C39: =B39 | D39: =C39 | E39: =D39 | F39: =E39 | G39: =F39 | H39: =G39 | I39: =H39 | J39: =I39 | ... M39: =L39 | N39: =SUM(B39:M39)
A40: ='Personal Budget Assumptions'!A40 | B40: ='Personal Budget Assumptions'!B40 | C40: =B40 | D40: =C40 | E40: =D40 | F40: =E40 | G40: =F40 | H40: =G40 | I40: =H40 | J40: =I40 | ... M40: =L40 | N40: =SUM(B40:M40)
A41: ='Personal Budget Assumptions'!A41 | B41: ='Personal Budget Assumptions'!B41 | C41: =B41 | D41: =C41 | E41: =D41 | F41: =E41 | G41: =F41 | H41: =G41 | I41: =H41 | J41: =I41 | ... M41: =L41 | N41: =SUM(B41:M41)
A42: ='Personal Budget Assumptions'!A42 | B42: ='Personal Budget Assumptions'!B42 | C42: =B42 | D42: =C42 | E42: =D42 | F42: =E42 | G42: =F42 | H42: =G42 | I42: =H42 | J42: =I42 | ... M42: =L42 | N42: =SUM(B42:M42)
A43: ='Personal Budget Assumptions'!A43 | B43: ='Personal Budget Assumptions'!B43 | C43: =B43 | D43: =C43 | E43: =D43 | F43: =E43 | G43: =F43 | H43: =G43 | I43: =H43 | J43: =I43 | ... M43: =L43 | N43: =SUM(B43:M43)
A44: ='Personal Budget Assumptions'!A44 | B44: ='Personal Budget Assumptions'!B44 | C44: =B44 | D44: =C44 | E44: =D44 | F44: =E44 | G44: =F44 | H44: =G44 | I44: =H44 | J44: =I44 | ... M44: =L44 | N44: =SUM(B44:M44)
A45: ='Personal Budget Assumptions'!A45 | B45: ='Personal Budget Assumptions'!B45 | C45: =B45 | D45: =C45 | E45: =D45 | F45: =E45 | G45: =F45 | H45: =G45 | I45: =H45 | J45: =I45 | ... M45: =L45 | N45: =SUM(B45:M45)
A46: ='Personal Budget Assumptions'!A46 | B46: ='Personal Budget Assumptions'!B46 | C46: =B46 | D46: =C46 | E46: =D46 | F46: =E46 | G46: =F46 | H46: =G46 | I46: =H46 | J46: =I46 | ... M46: =L46 | N46: =SUM(B46:M46)
...

Sheet Breakdown
C3: Budget
C4: Monthly Expenses | G4: Monthly Expenses | H4: Annual Expenses
D5: <-> | E5: <+> | G5: =D24+(-E24) | H5: =G5*12
C6: Health Insurance | D6: 609 | J6: Monthly Salary | K6: Months
G7: =J7*K7 | H7: Salary | J7: 7000 | K7: ='Kate Co Breakdown'!I5
C8: Chicago | D8: 0 | E8: =Chicago!F11 | H8: Taxes
G9: =G7 | H9: Take- Home
C10: Monthly Spending | D10: ='Monthly Spending'!D26 | G10: =G9/K7 | H10: Monthly available less taxes
G11: =G10-G5 | H11: Residual
C12: Mercedes | D12: 1125
K13: 3264.96
C14: State Farm | D14: ='Monthly Spending'!H33
C16: Home Security | D16: 41.6
C18: Northwestern Mutual | D18: 400
C20: Scottsdale | E20: =Scottsdale!F12
G21: E*Trade
G22: =G11
G23: 12
D24: =SUM(D6:D21) | E24: =SUM(E7:E22) | G24: =G22*G23

Sheet Monthly Spending
B1: Monthly Budget
C3: Monthly Disposable
C5: Clothing | D5: 0
C6: Dry Cleaning and Tailor | D6: 100
C7: Gas | D7: 150
C8: Doc | D8: 100
C9: Groceries | D9: 970
C10: Housekeeping | D10: 0 | K10: Personal
C11: Personal Stuff | D11: =N14/12 | K11: Dr. Perez | L11: 585 | M11: 4 | N11: =L11*M11
C12: Pierce | D12: 130 | K12: Face Other | L12: 152 | M12: 12 | N12: =L12*M12
C13: Nails | D13: 175 | K13: Haircut | L13: 500 | M13: 7 | N13: =L13*M13
C14: Personal Grooming | D14: =N14/12 | N14: =SUM(N11:N13)
C15: Pool | D15: 110 | G15: Streaming / Gym
C16: Subscriptions | D16: =H26 | G16: Apple | H16: =K22
C17: Car Wash | D17: 24 | G17: Audible | H17: 16.18 | K17: Apple
K18: 2.99
G19: Peacock | H19: 12 | K19: 4.32 | L19: Apple Storage
G20: Fubo | H20: 70 | K20: 12.99 | L20: Apple TV
G21: Parmount | H21: 15 | K21: 9.73 | L21: Amazon Prime
G22: Lifetime | H22: 151 | K22: =SUM(K18:K21)
G23: Netflix | H23: 21
G24: Spotify | H24: 13
G25: Hulu | H25: 14.06
C26: Total Monthly Expenses | D26: =SUM(D5:D24) | H26: =SUM(H16:H25)
G29: State Farm
G30: Car | H30: 497
G31: Dallas Home Owners | H31: 395
G32: Personal
H33: =SUM(H30:H32)
G34: Bi-Annually | H34: =H30*6
N49: Oct
O61: =SUM(O48:O60) | P61: =SUM(P48:P60) | Q61: =SUM(Q48:Q60) | R61: =SUM(R48:R60) | S61: =SUM(S48:S60)
O86: =O61+O46+#REF! | P86: =P61+P46+#REF! | Q86: =Q61+Q46+#REF! | R86: =R61+R46+#REF! | S86: =S61+S46+#REF!
O87: =O86/3 | P87: =P86/3 | Q87: =Q86/3 | R87: =R86/3 | S87: =S86/3

Sheet Chicago
C2: Chicago
C4: Mortgage | F4: 1218
C5: Association | F5: 933
C6: Direct TV | F6: 24
C7: Electricity | F7: 0
C9: Total | F9: =SUM(F4:F8)
C10: Less: Rent | F10: 2400
C11: After Expenses & Rent | F11: =F10-F9

Sheet Scottsdale
C3: Scottsdale | J3: HELOC | M3: HELOC Xtra
I4: Current | J4: 46895 | L4: Current | M4: 46895
C5: Mortgage | F5: 2378 | G5: Clickpay | I5: Payment | J5: =F6 | L5: Payment | M5: =F6+F7
C6: HELOC | F6: 500
C7: Xtra | F7: 0 | I7: Months | J7: =J4/J5 | L7: Months | M7: =M4/M5
C8: Association | F8: 1042 | I8: Years | J8: =J7/12 | L8: Years | M8: =M7/12
C10: Total | F10: =F5+F6+F8
C11: Rent | F11: 3500
C12: After Expenses & Rent | F12: =F11-F10
